Workbook

Sheet SkillActive
A1: 技能 | B1: (nouse)策划说明 | C1: 职业 | D1: 武器类型 | E1: (nouse)等阶 | F1: (nouse)类型 | G1: (nouse)编号 | H1: 对应战斗技能表id | I1: 对应特技id | J1: 对应技能书组 | K1: 可镶嵌的技能宝石组 | L1: 未解锁提示
A2: id.p | B2: desc999 | C2: occupation | D2: weaponType | E2: rank | F2: type | G2: order | H2: skill | I2: stunt | J2: skillBook | K2: skillGem | L2: lockTip
A3: number | B3: string | C3: numberArr | D3: numberArr | E3: string | F3: string | G3: string | H3: number2 | I3: number2 | J3: number | K3: numberArr | L3: string
A4: =E4*100000+F4*1000+G4 -> 101001 | B4: 专注斩 | C4: 1|2|3|4|5|6|7 | D4: 11002 | E4: 1 | F4: 1 | G4: 1 | H4: 1110000050 | J4: =A4 -> 101001 | K4: 1|2|3|4|5|6|7|8|9|10|11|12|13|14|15|16|17|18|19|20|21|22|23
A5: =E5*100000+F5*1000+G5 -> 101002 | B5: 旋风斩 | C5: 1|2|3|4|5|6|7 | D5: 11002 | E5: 1 | F5: 1 | G5: 2 | H5: 1110000040 | J5: =A5 -> 101002 | K5: 1|2|3|4|5|6|7|8|9|10|11|12|13|14|15|16|17|18|19|20|21|22|23
A6: =E6*100000+F6*1000+G6 -> 101003 | B6: 月光斩 | C6: 1|2|3|4|5|6|7 | D6: 11002 | E6: 1 | F6: 1 | G6: 3 | H6: 1110000010 | J6: =A6 -> 101003 | K6: 1|2|3|4|5|6|7|8|9|10|11|12|13|14|15|16|17|18|19|20|21|22|23
A7: =E7*100000+F7*1000+G7 -> 101004 | B7: 混沌刺击 | C7: 1|2|3|4|5|6|7 | D7: 11002 | E7: 1 | F7: 1 | G7: 4 | H7: 1110000030 | J7: =A7 -> 101004 | K7: 1|2|3|4|5|6|7|8|9|10|11|12|13|14|15|16|17|18|19|20|21|22|23
A8: =E8*100000+F8*1000+G8 -> 102001 | B8: 冥地喷涌 | C8: 1|2|3|4|5|6|7 | D8: 11003 | E8: 1 | F8: 2 | G8: 1 | H8: 1120000040 | J8: =A8 -> 102001 | K8: 1|2|3|4|5|6|7|8|9|10|11|12|13|14|15|16|17|18|19|20|21|22|23
A9: =E9*100000+F9*1000+G9 -> 102002 | B9: 冰霜新星 | C9: 1|2|3|4|5|6|7 | D9: 11001 | E9: 1 | F9: 2 | G9: 2 | H9: 1120000130 | J9: =A9 -> 102002 | K9: 1|2|3|4|5|6|7|8|9|10|11|12|13|14|15|16|17|18|19|20|21|22|23
A10: =E10*100000+F10*1000+G10 -> 102003 | B10: 移形换影 | C10: 1|2|3|4|5|6|7 | D10: 11001|11002|11003 | E10: 1 | F10: 2 | G10: 3 | I10: 2120000011 | J10: =A10 -> 102003 | K10: 1|2|3|4|5|6|7|8|9|10|11|12|13|14|15|16|17|18|19|20|21|22|23
A11: =E11*100000+F11*1000+G11 -> 102004 | B11: 法术旋龙 | C11: 1|2|3|4|5|6|7 | D11: 11001 | E11: 1 | F11: 2 | G11: 4 | H11: 1120000020 | J11: =A11 -> 102004 | K11: 1|2|3|4|5|6|7|8|9|10|11|12|13|14|15|16|17|18|19|20|21|22|23
A12: =E12*100000+F12*1000+G12 -> 102005 | B12: 火球术 | C12: 1|2|3|4|5|6|7 | D12: 11001 | E12: 1 | F12: 2 | G12: 5 | H12: 1120000080 | J12: =A12 -> 102005 | K12: 1|2|3|4|5|6|7|8|9|10|11|12|13|14|15|16|17|18|19|20|21|22|23
A13: =E13*100000+F13*1000+G13 -> 102006 | B13: 混沌陨星 | C13: 1|2|3|4|5|6|7 | D13: 11003 | E13: 1 | F13: 2 | G13: 6 | H13: 1120000140 | J13: =A13 -> 102006 | K13: 1|2|3|4|5|6|7|8|9|10|11|12|13|14|15|16|17|18|19|20|21|22|23
A14: =E14*100000+F14*1000+G14 -> 201001 | B14: 闪电之捷 | C14: 1|2|3|4|5|6|7 | D14: 11001|11002|11003 | E14: 2 | F14: 1 | G14: 1 | I14: 2110000010 | J14: =A14 -> 201001 | K14: 1|2|3|4|5|6|7|8|9|10|11|12|13|14|15|16|17|18|19|20|21|22|23
A15: =E15*100000+F15*1000+G15 -> 201002 | B15: 拔刀斩 | C15: 1|2|3|4|5|6|7 | D15: 11002 | E15: 2 | F15: 1 | G15: 2 | H15: 1110000020 | J15: =A15 -> 201002 | K15: 1|2|3|4|5|6|7|8|9|10|11|12|13|14|15|16|17|18|19|20|21|22|23
A16: =E16*100000+F16*1000+G16 -> 201003 | B16: 气刃纵斩 | C16: 1|2|3|4|5|6|7 | D16: 11002 | E16: 2 | F16: 1 | G16: 3 | H16: 1110000060 | J16: =A16 -> 201003 | K16: 1|2|3|4|5|6|7|8|9|10|11|12|13|14|15|16|17|18|19|20|21|22|23
A17: =E17*100000+F17*1000+G17 -> 202001 | B17: 回旋龙卷 | C17: 1|2|3|4|5|6|7 | D17: 11001 | E17: 2 | F17: 2 | G17: 1 | H17: 1120000050 | J17: =A17 -> 202001 | K17: 1|2|3|4|5|6|7|8|9|10|11|12|13|14|15|16|17|18|19|20|21|22|23
A18: =E18*100000+F18*1000+G18 -> 204001 | B18: 魔力满溢 | C18: 1|2|3|4|5|6|7 | D18: 0 | E18: 2 | F18: 4 | G18: 1 | I18: 2140000140 | J18: =A18 -> 204001 | K18: 1|2|3|4|5|6|7|8|9|10|11|12|13|14|15|16|17|18|19|20|21|22|23
A19: =E19*100000+F19*1000+G19 -> 301001 | B19: 灰烬之捷 | C19: 1|2|3|4|5|6|7 | D19: 11001|11002|11003 | E19: 3 | F19: 1 | G19: 1 | I19: 2110000020 | J19: =A19 -> 301001 | K19: 1|2|3|4|5|6|7|8|9|10|11|12|13|14|15|16|17|18|19|20|21|22|23
A20: =E20*100000+F20*1000+G20 -> 301002 | B20: 月神赐福 | C20: 1|2|3|4|5|6|7 | D20: 11002 | E20: 3 | F20: 1 | G20: 2 | H20: 1140000010 | J20: =A20 -> 301002 | K20: 1|2|3|4|5|6|7|8|9|10|11|12|13|14|15|16|17|18|19|20|21|22|23
A21: =E21*100000+F21*1000+G21 -> 302001 | B21: 回响 | C21: 1|2|3|4|5|6|7 | D21: 11001 | E21: 3 | F21: 2 | G21: 1 | H21: 1120000010 | J21: =A21 -> 302001 | K21: 1|2|3|4|5|6|7|8|9|10|11|12|13|14|15|16|17|18|19|20|21|22|23
A22: =E22*100000+F22*1000+G22 -> 305001 | B22: 极地战吼 | C22: 1|2|3|4|5|6|7 | D22: 11001|11002|11003 | E22: 3 | F22: 5 | G22: 1 | H22: 1140000020 | J22: =A22 -> 305001 | K22: 1|2|3|4|5|6|7|8|9|10|11|12|13|14|15|16|17|18|19|20|21|22|23
A23: =E23*100000+F23*1000+G23 -> 401001 | B23: 冰霜之捷 | C23: 1|2|3|4|5|6|7 | D23: 11001|11002|11003 | E23: 4 | F23: 1 | G23: 1 | I23: 2110000030 | J23: =A23 -> 401001 | K23: 1|2|3|4|5|6|7|8|9|10|11|12|13|14|15|16|17|18|19|20|21|22|23
A24: =E24*100000+F24*1000+G24 -> 401002 | B24: 大地之怒 | C24: 1|2|3|4|5|6|7 | D24: 11001 | E24: 4 | F24: 1 | G24: 2 | I24: 2120000030 | J24: =A24 -> 401002 | K24: 1|2|3|4|5|6|7|8|9|10|11|12|13|14|15|16|17|18|19|20|21|22|23
A25: =E25*100000+F25*1000+G25 -> 404001 | B25: 元素脉冲 | C25: 1|2|3|4|5|6|7 | D25: 0 | E25: 4 | F25: 4 | G25: 1 | I25: 2140000080 | J25: =A25 -> 404001 | K25: 1|2|3|4|5|6|7|8|9|10|11|12|13|14|15|16|17|18|19|20|21|22|23
A26: =E26*100000+F26*1000+G26 -> 404002 | B26: 毁灭意志 | C26: 1|2|3|4|5|6|7 | D26: 0 | E26: 4 | F26: 4 | G26: 2 | I26: 2140000110 | J26: =A26 -> 404002 | K26: 1|2|3|4|5|6|7|8|9|10|11|12|13|14|15|16|17|18|19|20|21|22|23
A27: =E27*100000+F27*1000+G27 -> 501001 | B27: 迅捷 | E27: 5 | F27: 1 | G27: 1 | I27: 2114000020 | J27: =A27 -> 501001 | K27: 1|2|3|4|5|6|7|8|9|10|11|12|13|14|15|16|17|18|19|20|21|22|23
A28: =E28*100000+F28*1000+G28 -> 501002 | B28: 吞噬 | E28: 5 | F28: 1 | G28: 2 | I28: 2150000020 | J28: =A28 -> 501002 | K28: 1|2|3|4|5|6|7|8|9|10|11|12|13|14|15|16|17|18|19|20|21|22|23
A29: =E29*100000+F29*1000+G29 -> 504001 | B29: 迅捷 | C29: 1|2|3|4|5|6|7 | D29: 0 | E29: 5 | F29: 4 | G29: 1 | I29: 2114000020 | J29: =A29 -> 504001 | K29: 1|2|3|4|5|6|7|8|9|10|11|12|13|14|15|16|17|18|19|20|21|22|23
A30: =E30*100000+F30*1000+G30 -> 504002 | B30: 精准投射 | C30: 1|2|3|4|5|6|7 | D30: 0 | E30: 5 | F30: 4 | G30: 2 | I30: 2140000040 | J30: =A30 -> 504002 | K30: 1|2|3|4|5|6|7|8|9|10|11|12|13|14|15|16|17|18|19|20|21|22|23
A31: =E31*100000+F31*1000+G31 -> 504003 | B31: 领域扩张 | C31: 1|2|3|4|5|6|7 | D31: 0 | E31: 5 | F31: 4 | G31: 3 | I31: 2140000050 | J31: =A31 -> 504003 | K31: 1|2|3|4|5|6|7|8|9|10|11|12|13|14|15|16|17|18|19|20|21|22|23
A32: =E32*100000+F32*1000+G32 -> 504004 | B32: 狂暴 | C32: 1|2|3|4|5|6|7 | D32: 0 | E32: 5 | F32: 4 | G32: 4 | I32: 2140000060 | J32: =A32 -> 504004 | K32: 1|2|3|4|5|6|7|8|9|10|11|12|13|14|15|16|17|18|19|20|21|22|23
A33: =E33*100000+F33*1000+G33 -> 504005 | B33: 生命再生 | C33: 1|2|3|4|5|6|7 | D33: 0 | E33: 5 | F33: 4 | G33: 5 | I33: 2140000070 | J33: =A33 -> 504005 | K33: 1|2|3|4|5|6|7|8|9|10|11|12|13|14|15|16|17|18|19|20|21|22|23

Sheet SkillSlot
A1: id | B1: 解锁等级 | C1: 备注(nouse) | D1: 优先级
A2: id.p | B2: level | C2: desc999 | D2: priority
A3: number | B3: number | C3: string | D3: number
A4: 1 | B4: 0 | C4: 槽位1 | D4: 5
A5: 2 | B5: 2 | C5: 槽位2 | D5: 4
A6: 3 | B6: 5 | C6: 槽位3 | D6: 3
A7: 4 | B7: 10 | C7: 槽位4 | D7: 2
A8: 5 | B8: 15 | C8: 槽位5 | D8: 1

Sheet SkillGem
A1: 技能宝石id | B1: 宝石组id | C1: (nouse)编号 | D1: 宝石等级(废弃) | E1: 图标 | F1: 名称 | G1: 描述 | H1: 词缀id | I1: 词缀数值 | J1: 被动表id | K1: 词缀数值 | L1: 提供属性-启用加属性 | M1: 自选箱最低可选等级 | N1: 所属阶级
A2: id.p | B2: group | C2: order | D2: level | E2: icon | F2: name | G2: desc | H2: skillAffix | I2: affixValue | J2: stunt | K2: stuntValue | L2: attr | M2: selectLimitLevel | N2: stageLevel
A3: number | B3: number | C3: string | D3: number | E3: string | F3: string | G3: string | H3: numberArr | I3: object | J3: numberArr | K3: object | L3: object | M3: number | N3: number
A4: =100000+B4*100+C4 -> 100101 | B4: 1 | C4: 1 | D4: =M4 -> 1 | E4: skill/sect/101101 | F4: 范围扩大·一 | G4: 辅助有范围标签的技能，范围效果扩大25% | H4: 10032 | I4: [[0.25]] | M4: 1 | N4: =M4 -> 1
A5: =100000+B5*100+C5 -> 100102 | B5: 1 | C5: 2 | D5: 2 | E5: skill/sect/101102 | F5: 范围扩大·二 | G5: 辅助有范围标签的技能，范围效果扩大50% | H5: 10032 | I5: [[0.5]] | M5: 4 | N5: 4
A6: =100000+B6*100+C6 -> 100201 | B6: =B4+1 -> 2 | C6: 1 | D6: 1 | E6: skill/sect/101201 | F6: 投射物增加·一 | G6: 辅助有投射物标签的技能，使其生成的投射物数量+1，造成的伤害额外降低30% | H6: 10038|10046 | I6: [[1],[-0.3]] | M6: 1 | N6: =M6 -> 1
A7: =100000+B7*100+C7 -> 100202 | B7: =B5+1 -> 2 | C7: 2 | D7: 1 | E7: skill/sect/101201 | F7: 投射物增加·二 | G7: 辅助有投射物标签的技能，使其生成的投射物数量+2，造成的伤害额外降低30% | H7: 10038|10046 | I7: [[2],[-0.3]] | M7: 4 | N7: 4
A8: =100000+B8*100+C8 -> 100204 | B8: 2 | C8: 4 | D8: 5 | E8: skill/sect/101201 | F8: 新星投射物 | G8: 投射物数量+5，投射物变更为环形发射，投射物伤害总降50% | H8: 10043 | M8: 5 | N8: =M8 -> 5
A9: =100000+B9*100+C9 -> 100301 | B9: =B6+1 -> 3 | C9: 1 | D9: =M9 -> 1 | E9: skill/sect/101301 | F9: 快速攻击·一 | G9: 辅助有攻击标签的技能，攻击速度提高15% | H9: 10031 | I9: [[0.15]] | M9: 1 | N9: =M9 -> 1
A10: =100000+B10*100+C10 -> 100302 | B10: 3 | C10: 2 | D10: 2 | E10: skill/sect/101302 | F10: 快速攻击·二 | G10: 辅助有攻击标签的技能，攻击速度提高30% | H10: 10031 | I10: [[0.3]] | M10: 4 | N10: 4
A11: =100000+B11*100+C11 -> 100401 | B11: 4 | C11: 1 | D11: 1 | E11: skill/sect/102101 | F11: 范围集中·一 | G11: 辅助有范围标签的技能，使其范围总降50%，伤害额外提高15% | H11: 10037 | I11: [[0.15]] | M11: 2 | N11: =M11 -> 2
A12: =100000+B12*100+C12 -> 100402 | B12: 4 | C12: 2 | D12: 2 | E12: skill/sect/102102 | F12: 范围集中·二 | G12: 辅助有范围标签的技能，使其范围总降50%，伤害额外提高30% | H12: 10037 | I12: [[0.3]] | M12: 4 | N12: =M12 -> 4
A13: =100000+B13*100+C13 -> 100501 | B13: 5 | C13: 1 | D13: 3 | E13: skill/sect/102103 | F13: 冻结·一 | G13: 辅助有冰霜标签的技能，使其冻结的积蓄值额外提高25% | H13: 10033 | I13: [[0.25]] | M13: 2 | N13: 2
A14: =100000+B14*100+C14 -> 100502 | B14: 5 | C14: 2 | D14: 4 | E14: skill/sect/102104 | F14: 冻结·二 | G14: 辅助有冰霜标签的技能，使其冻结的积蓄值额外提高50% | H14: 10033 | I14: [[0.5]] | M14: 5 | N14: =M14 -> 5
A15: =100000+B15*100+C15 -> 100601 | B15: 6 | C15: 1 | D15: 5 | E15: skill/sect/102104 | F15: 持续时间延长·一 | G15: 辅助有持续性技能标签的技能，使其持续时间提高20% | H15: 10034 | I15: [[0.2]] | M15: 2 | N15: =M15 -> 2
A16: =100000+B16*100+C16 -> 100602 | B16: 6 | C16: 2 | D16: =D11 -> 1 | E16: skill/sect/102201 | F16: 持续时间延长·二 | G16: 辅助有持续性技能标签的技能，使其持续时间提高30% | H16: 10034 | I16: [[0.3]] | M16: 4 | N16: =M16 -> 4
A17: =100000+B17*100+C17 -> 100701 | B17: 7 | C17: 1 | D17: =D12 -> 2 | E17: skill/sect/102202 | F17: 冷却回复·一 | G17: 辅助技能，使其冷却回复率增加15% | H17: 10106 | I17: [[0.15]] | M17: 2 | N17: 2
A18: =100000+B18*100+C18 -> 100702 | B18: 7 | C18: 2 | D18: =D13 -> 3 | E18: skill/sect/102203 | F18: 冷却回复·二 | G18: 辅助技能，使其冷却回复率增加25% | H18: 10106 | I18: [[0.25]] | M18: 5 | N18: =M18 -> 5
A19: =100000+B19*100+C19 -> 100801 | B19: 8 | C19: 1 | D19: =D14 -> 4 | E19: skill/sect/102204 | F19: 多重范围释放 | G19: 辅助有触发标签的技能，使其伤害总降20%，重复使用技能3次，不能对同一目标使用 | H19: 10036 | M19: 3 | N19: =M19 -> 3
A20: =100000+B20*100+C20 -> 100901 | B20: 9 | C20: 1 | D20: 2 | E20: skill/sect/102204 | F20: 无边能量·一 | G20: 使获得的能量提高25% | H20: 10040 | I20: [[0.25]] | M20: 2 | N20: =M20 -> 2
A21: =100000+B21*100+C21 -> 100902 | B21: 9 | C21: 2 | D21: 4 | E21: skill/sect/102204 | F21: 无边能量·二 | G21: 使获得的能量提高50% | H21: 10040 | I21: [[0.5]] | M21: 4 | N21: =M21 -> 4
A22: =100000+B22*100+C22 -> 101001 | B22: 10 | C22: 1 | D22: 3 | E22: skill/sect/102204 | F22: 冻结时间增加·一 | G22: 被冰冻敌人的冻结时间额外提高25% | H22: 10041 | I22: [[0.25]] | M22: 2 | N22: 2
A23: =100000+B23*100+C23 -> 101002 | B23: 10 | C23: 2 | D23: 5 | E23: skill/sect/102204 | F23: 冻结时间增加·二 | G23: 被冰冻敌人的冻结时间额外提高50% | H23: 10041 | I23: [[0.5]] | M23: 5 | N23: =M23 -> 5
A24: =100000+B24*100+C24 -> 101101 | B24: 11 | C24: 1 | D24: 2 | E24: skill/sect/102204 | F24: 元素军械·一 | G24: 元素伤害额外提高15% | H24: 10042 | I24: [[0.15]] | M24: 1 | N24: 1
A25: =100000+B25*100+C25 -> 101102 | B25: 11 | C25: 2 | D25: 5 | E25: skill/sect/102204 | F25: 元素军械·二 | G25: 元素伤害额外提高25% | H25: 10042 | I25: [[0.25]] | M25: 5 | N25: =M25 -> 5
A26: =100000+B26*100+C26 -> 101201 | B26: 12 | C26: 1 | D26: 3 | E26: skill/sect/102204 | F26: 闪电偏转 | G26: 闪电倍率提高25%，火焰倍率和冰冷倍率下降25% | H26: 10044 | M26: 1 | N26: 1
A27: =100000+B27*100+C27 -> 101301 | B27: 13 | C27: 1 | D27: 4 | E27: skill/sect/102204 | F27: 冰冷偏转 | G27: 冰冷倍率提高25%，火焰倍率和闪电倍率下降25% | H27: 10045 | M27: 1 | N27: =M27 -> 1
A28: =100000+B28*100+C28 -> 101401 | B28: 14 | C28: 1 | D28: 5 | E28: skill/sect/102204 | F28: 火焰偏转 | G28: 火焰倍率提高25%，闪电倍率和冰冷倍率下降25% | H28: 10046 | M28: 1 | N28: 1
A29: =100000+B29*100+C29 -> 101501 | B29: 15 | C29: 1 | D29: 1 | E29: skill/sect/102101 | F29: 沉重挥舞·一 | G29: 攻击速度降低10%，近战物理伤害额外提高15% | H29: 10047 | I29: [[0.15]] | M29: 2 | N29: 2
A30: =100000+B30*100+C30 -> 101502 | B30: 15 | C30: 2 | D30: 2 | E30: skill/sect/102102 | F30: 沉重挥舞·二 | G30: 攻击速度降低10%，近战物理伤害额外提高30% | H30: 10047 | I30: [[0.3]] | M30: 4 | N30: =M30 -> 4
A31: =100000+B31*100+C31 -> 101601 | B31: 16 | C31: 1 | D31: 1 | E31: skill/sect/102101 | F31: 迎寒而上·一 | G31: 被辅助技能冻结敌人时，获得15%的额外冰冷伤害，持续6秒 | H31: 10048 | I31: [[0.15]] | M31: 1 | N31: 1
A32: =100000+B32*100+C32 -> 101602 | B32: 16 | C32: 2 | D32: 2 | E32: skill/sect/102102 | F32: 迎寒而上·二 | G32: 被辅助技能冻结敌人时，获得25%的额外冰冷伤害，持续6秒 | H32: 10048 | I32: [[0.25]] | M32: 5 | N32: =M32 -> 5
A33: =100000+B33*100+C33 -> 101701 | B33: 17 | C33: 1 | D33: 1 | E33: skill/sect/102101 | F33: 猛毒·一 | G33: 被辅助技能，击中中毒目标时，每层中毒效果伤害额外提高3%，上限5层 | J33: 3140000040 | K33: [[0.03]] | M33: 2 | N33: 2
A34: =100000+B34*100+C34 -> 101702 | B34: 17 | C34: 2 | D34: 2 | E34: skill/sect/102102 | F34: 猛毒·二 | G34: 被辅助技能，击中中毒目标时，每层中毒效果伤害额外提高5%，上限5层 | J34: 3140000040 | K34: [[0.05]] | M34: 5 | N34: =M34 -> 5
A35: =100000+B35*100+C35 -> 101801 | B35: 18 | C35: 1 | D35: 1 | E35: skill/sect/102101 | F35: 毒化·一 | G35: 被辅助技能，混沌伤害额外提高10% ，中毒几率增加20% | H35: 10128|10051 | I35: [[0.10],[0.20]] | M35: 1 | N35: 1
A36: =100000+B36*100+C36 -> 101802 | B36: 18 | C36: 2 | D36: 2 | E36: skill/sect/102102 | F36: 毒化·二 | G36: 被辅助技能，混沌伤害额外提高20% ，中毒几率增加40% | H36: 10128|10051 | I36: [[0.20],[0.40]] | M36: 4 | N36: =M36 -> 4
A37: =100000+B37*100+C37 -> 101901 | B37: 19 | C37: 1 | D37: 1 | E37: skill/sect/102101 | F37: 包围·一 | G37: 辅助有环绕标签的技能，环绕子弹数量+1，造成的伤害额外降低30% | H37: 10131|10046 | I37: [[1],[-0.3]] | M37: 2 | N37: 2
A38: =100000+B38*100+C38 -> 101902 | B38: 19 | C38: 2 | D38: 2 | E38: skill/sect/102102 | F38: 包围·二 | G38: 辅助有环绕标签的技能，环绕子弹数量+1 | H38: 10131 | I38: [[1]] | M38: 4 | N38: =M38 -> 4
A39: =100000+B39*100+C39 -> 102001 | B39: 20 | C39: 1 | D39: 1 | E39: skill/sect/102101 | F39: 盘旋·一 | G39: 辅助有环绕标签的技能，被辅助技能的环绕子弹速度提高30% | H39: 10132 | I39: [[0.3]] | M39: 2 | N39: =M39 -> 2
A40: =100000+B40*100+C40 -> 102002 | B40: 20 | C40: 2 | D40: 2 | E40: skill/sect/102102 | F40: 盘旋·二 | G40: 辅助有环绕标签的技能，被辅助技能的环绕子弹速度提高50% | H40: 10132 | I40: [[0.5]] | M40: 4 | N40: =M40 -> 4
...

Sheet SkillBook
A1: 技能书id | B1: 职业 | C1: 技能书组 | D1: 等级 | E1: 备注(nouse) | F1: 自选箱最低可选等级 | G1: 所属阶级
A2: id.p | B2: occupation | C2: group | D2: level | E2: desc999 | F2: selectLimitLevel | G2: stageLevel
A3: number | B3: numberArr | C3: number | D3: number | E3: string | F3: number | G3: number
A4: =C4*100+D4 -> 10100101 | B4: =_xlfn.XLOOKUP(C4,SkillActive!$A:$A,SkillActive!C:C,,0) -> 1|2|3|4|5|6|7 | C4: 101001 | D4: 1 | E4: =_xlfn.XLOOKUP(C4,SkillActive!A:A,SkillActive!B:B,,,) -> 专注斩 | F4: =D4 -> 1 | G4: =_xlfn.XLOOKUP(C4,SkillActive!$A:$A,SkillActive!E:E,,0) -> 1
A5: =C5*100+D5 -> 10100102 | B5: =_xlfn.XLOOKUP(C5,SkillActive!$A:$A,SkillActive!C:C,,0) -> 1|2|3|4|5|6|7 | C5: =C4 -> 101001 | D5: 2 | E5: =_xlfn.XLOOKUP(C5,SkillActive!A:A,SkillActive!B:B,,,) -> 专注斩 | F5: =D5 -> 2 | G5: =_xlfn.XLOOKUP(C5,SkillActive!$A:$A,SkillActive!E:E,,0) -> 1
A6: =C6*100+D6 -> 10100103 | B6: =_xlfn.XLOOKUP(C6,SkillActive!$A:$A,SkillActive!C:C,,0) -> 1|2|3|4|5|6|7 | C6: =C5 -> 101001 | D6: 3 | E6: =_xlfn.XLOOKUP(C6,SkillActive!A:A,SkillActive!B:B,,,) -> 专注斩 | F6: =D6 -> 3 | G6: =_xlfn.XLOOKUP(C6,SkillActive!$A:$A,SkillActive!E:E,,0) -> 1
A7: =C7*100+D7 -> 10100104 | B7: =_xlfn.XLOOKUP(C7,SkillActive!$A:$A,SkillActive!C:C,,0) -> 1|2|3|4|5|6|7 | C7: =C6 -> 101001 | D7: 4 | E7: =_xlfn.XLOOKUP(C7,SkillActive!A:A,SkillActive!B:B,,,) -> 专注斩 | F7: =D7 -> 4 | G7: =_xlfn.XLOOKUP(C7,SkillActive!$A:$A,SkillActive!E:E,,0) -> 1
A8: =C8*100+D8 -> 10100105 | B8: =_xlfn.XLOOKUP(C8,SkillActive!$A:$A,SkillActive!C:C,,0) -> 1|2|3|4|5|6|7 | C8: =C7 -> 101001 | D8: 5 | E8: =_xlfn.XLOOKUP(C8,SkillActive!A:A,SkillActive!B:B,,,) -> 专注斩 | F8: =D8 -> 5 | G8: =_xlfn.XLOOKUP(C8,SkillActive!$A:$A,SkillActive!E:E,,0) -> 1
A9: =C9*100+D9 -> 10100106 | B9: =_xlfn.XLOOKUP(C9,SkillActive!$A:$A,SkillActive!C:C,,0) -> 1|2|3|4|5|6|7 | C9: =C8 -> 101001 | D9: 6 | E9: =_xlfn.XLOOKUP(C9,SkillActive!A:A,SkillActive!B:B,,,) -> 专注斩 | F9: =D9 -> 6 | G9: =_xlfn.XLOOKUP(C9,SkillActive!$A:$A,SkillActive!E:E,,0) -> 1
A10: =C10*100+D10 -> 10100107 | B10: =_xlfn.XLOOKUP(C10,SkillActive!$A:$A,SkillActive!C:C,,0) -> 1|2|3|4|5|6|7 | C10: =C9 -> 101001 | D10: 7 | E10: =_xlfn.XLOOKUP(C10,SkillActive!A:A,SkillActive!B:B,,,) -> 专注斩 | F10: =D10 -> 7 | G10: =_xlfn.XLOOKUP(C10,SkillActive!$A:$A,SkillActive!E:E,,0) -> 1
A11: =C11*100+D11 -> 10100108 | B11: =_xlfn.XLOOKUP(C11,SkillActive!$A:$A,SkillActive!C:C,,0) -> 1|2|3|4|5|6|7 | C11: =C10 -> 101001 | D11: 8 | E11: =_xlfn.XLOOKUP(C11,SkillActive!A:A,SkillActive!B:B,,,) -> 专注斩 | F11: =D11 -> 8 | G11: =_xlfn.XLOOKUP(C11,SkillActive!$A:$A,SkillActive!E:E,,0) -> 1
A12: =C12*100+D12 -> 10100109 | B12: =_xlfn.XLOOKUP(C12,SkillActive!$A:$A,SkillActive!C:C,,0) -> 1|2|3|4|5|6|7 | C12: =C11 -> 101001 | D12: 9 | E12: =_xlfn.XLOOKUP(C12,SkillActive!A:A,SkillActive!B:B,,,) -> 专注斩 | F12: =D12 -> 9 | G12: =_xlfn.XLOOKUP(C12,SkillActive!$A:$A,SkillActive!E:E,,0) -> 1
A13: =C13*100+D13 -> 10100110 | B13: =_xlfn.XLOOKUP(C13,SkillActive!$A:$A,SkillActive!C:C,,0) -> 1|2|3|4|5|6|7 | C13: =C12 -> 101001 | D13: 10 | E13: =_xlfn.XLOOKUP(C13,SkillActive!A:A,SkillActive!B:B,,,) -> 专注斩 | F13: =D13 -> 10 | G13: =_xlfn.XLOOKUP(C13,SkillActive!$A:$A,SkillActive!E:E,,0) -> 1
A14: =C14*100+D14 -> 10100111 | B14: =_xlfn.XLOOKUP(C14,SkillActive!$A:$A,SkillActive!C:C,,0) -> 1|2|3|4|5|6|7 | C14: =C13 -> 101001 | D14: 11 | E14: =_xlfn.XLOOKUP(C14,SkillActive!A:A,SkillActive!B:B,,,) -> 专注斩 | F14: =D14 -> 11 | G14: =_xlfn.XLOOKUP(C14,SkillActive!$A:$A,SkillActive!E:E,,0) -> 1
A15: =C15*100+D15 -> 10100112 | B15: =_xlfn.XLOOKUP(C15,SkillActive!$A:$A,SkillActive!C:C,,0) -> 1|2|3|4|5|6|7 | C15: =C14 -> 101001 | D15: 12 | E15: =_xlfn.XLOOKUP(C15,SkillActive!A:A,SkillActive!B:B,,,) -> 专注斩 | F15: =D15 -> 12 | G15: =_xlfn.XLOOKUP(C15,SkillActive!$A:$A,SkillActive!E:E,,0) -> 1
A16: =C16*100+D16 -> 10100113 | B16: =_xlfn.XLOOKUP(C16,SkillActive!$A:$A,SkillActive!C:C,,0) -> 1|2|3|4|5|6|7 | C16: =C15 -> 101001 | D16: 13 | E16: =_xlfn.XLOOKUP(C16,SkillActive!A:A,SkillActive!B:B,,,) -> 专注斩 | F16: =D16 -> 13 | G16: =_xlfn.XLOOKUP(C16,SkillActive!$A:$A,SkillActive!E:E,,0) -> 1
... A19: =C19*100+D19 -> 10100116 | B19: =_xlfn.XLOOKUP(C19,SkillActive!$A:$A,SkillActive!C:C,,0) -> 1|2|3|4|5|6|7 | C19: =C18 -> 101001 | D19: 16 | E19: =_xlfn.XLOOKUP(C19,SkillActive!A:A,SkillActive!B:B,,,) -> 专注斩 | F19: =D19 -> 16 | G19: =_xlfn.XLOOKUP(C19,SkillActive!$A:$A,SkillActive!E:E,,0) -> 1
A20: =C20*100+D20 -> 10100201 | B20: =_xlfn.XLOOKUP(C20,SkillActive!$A:$A,SkillActive!C:C,,0) -> 1|2|3|4|5|6|7 | C20: =C4+1 -> 101002 | D20: =D4 -> 1 | E20: =_xlfn.XLOOKUP(C20,SkillActive!A:A,SkillActive!B:B,,,) -> 旋风斩 | F20: =D20 -> 1 | G20: =_xlfn.XLOOKUP(C20,SkillActive!$A:$A,SkillActive!E:E,,0) -> 1
A21: =C21*100+D21 -> 10100202 | B21: =_xlfn.XLOOKUP(C21,SkillActive!$A:$A,SkillActive!C:C,,0) -> 1|2|3|4|5|6|7 | C21: =C5+1 -> 101002 | D21: =D5 -> 2 | E21: =_xlfn.XLOOKUP(C21,SkillActive!A:A,SkillActive!B:B,,,) -> 旋风斩 | F21: =D21 -> 2 | G21: =_xlfn.XLOOKUP(C21,SkillActive!$A:$A,SkillActive!E:E,,0) -> 1
A22: =C22*100+D22 -> 10100203 | B22: =_xlfn.XLOOKUP(C22,SkillActive!$A:$A,SkillActive!C:C,,0) -> 1|2|3|4|5|6|7 | C22: =C6+1 -> 101002 | D22: =D6 -> 3 | E22: =_xlfn.XLOOKUP(C22,SkillActive!A:A,SkillActive!B:B,,,) -> 旋风斩 | F22: =D22 -> 3 | G22: =_xlfn.XLOOKUP(C22,SkillActive!$A:$A,SkillActive!E:E,,0) -> 1
A23: =C23*100+D23 -> 10100204 | B23: =_xlfn.XLOOKUP(C23,SkillActive!$A:$A,SkillActive!C:C,,0) -> 1|2|3|4|5|6|7 | C23: =C7+1 -> 101002 | D23: =D7 -> 4 | E23: =_xlfn.XLOOKUP(C23,SkillActive!A:A,SkillActive!B:B,,,) -> 旋风斩 | F23: =D23 -> 4 | G23: =_xlfn.XLOOKUP(C23,SkillActive!$A:$A,SkillActive!E:E,,0) -> 1
A24: =C24*100+D24 -> 10100205 | B24: =_xlfn.XLOOKUP(C24,SkillActive!$A:$A,SkillActive!C:C,,0) -> 1|2|3|4|5|6|7 | C24: =C8+1 -> 101002 | D24: =D8 -> 5 | E24: =_xlfn.XLOOKUP(C24,SkillActive!A:A,SkillActive!B:B,,,) -> 旋风斩 | F24: =D24 -> 5 | G24: =_xlfn.XLOOKUP(C24,SkillActive!$A:$A,SkillActive!E:E,,0) -> 1
A25: =C25*100+D25 -> 10100206 | B25: =_xlfn.XLOOKUP(C25,SkillActive!$A:$A,SkillActive!C:C,,0) -> 1|2|3|4|5|6|7 | C25: =C9+1 -> 101002 | D25: =D9 -> 6 | E25: =_xlfn.XLOOKUP(C25,SkillActive!A:A,SkillActive!B:B,,,) -> 旋风斩 | F25: =D25 -> 6 | G25: =_xlfn.XLOOKUP(C25,SkillActive!$A:$A,SkillActive!E:E,,0) -> 1
A26: =C26*100+D26 -> 10100207 | B26: =_xlfn.XLOOKUP(C26,SkillActive!$A:$A,SkillActive!C:C,,0) -> 1|2|3|4|5|6|7 | C26: =C10+1 -> 101002 | D26: =D10 -> 7 | E26: =_xlfn.XLOOKUP(C26,SkillActive!A:A,SkillActive!B:B,,,) -> 旋风斩 | F26: =D26 -> 7 | G26: =_xlfn.XLOOKUP(C26,SkillActive!$A:$A,SkillActive!E:E,,0) -> 1
A27: =C27*100+D27 -> 10100208 | B27: =_xlfn.XLOOKUP(C27,SkillActive!$A:$A,SkillActive!C:C,,0) -> 1|2|3|4|5|6|7 | C27: =C11+1 -> 101002 | D27: =D11 -> 8 | E27: =_xlfn.XLOOKUP(C27,SkillActive!A:A,SkillActive!B:B,,,) -> 旋风斩 | F27: =D27 -> 8 | G27: =_xlfn.XLOOKUP(C27,SkillActive!$A:$A,SkillActive!E:E,,0) -> 1
A28: =C28*100+D28 -> 10100209 | B28: =_xlfn.XLOOKUP(C28,SkillActive!$A:$A,SkillActive!C:C,,0) -> 1|2|3|4|5|6|7 | C28: =C12+1 -> 101002 | D28: =D12 -> 9 | E28: =_xlfn.XLOOKUP(C28,SkillActive!A:A,SkillActive!B:B,,,) -> 旋风斩 | F28: =D28 -> 9 | G28: =_xlfn.XLOOKUP(C28,SkillActive!$A:$A,SkillActive!E:E,,0) -> 1
A29: =C29*100+D29 -> 10100210 | B29: =_xlfn.XLOOKUP(C29,SkillActive!$A:$A,SkillActive!C:C,,0) -> 1|2|3|4|5|6|7 | C29: =C13+1 -> 101002 | D29: =D13 -> 10 | E29: =_xlfn.XLOOKUP(C29,SkillActive!A:A,SkillActive!B:B,,,) -> 旋风斩 | F29: =D29 -> 10 | G29: =_xlfn.XLOOKUP(C29,SkillActive!$A:$A,SkillActive!E:E,,0) -> 1
A30: =C30*100+D30 -> 10100211 | B30: =_xlfn.XLOOKUP(C30,SkillActive!$A:$A,SkillActive!C:C,,0) -> 1|2|3|4|5|6|7 | C30: =C14+1 -> 101002 | D30: =D14 -> 11 | E30: =_xlfn.XLOOKUP(C30,SkillActive!A:A,SkillActive!B:B,,,) -> 旋风斩 | F30: =D30 -> 11 | G30: =_xlfn.XLOOKUP(C30,SkillActive!$A:$A,SkillActive!E:E,,0) -> 1
A31: =C31*100+D31 -> 10100212 | B31: =_xlfn.XLOOKUP(C31,SkillActive!$A:$A,SkillActive!C:C,,0) -> 1|2|3|4|5|6|7 | C31: =C15+1 -> 101002 | D31: =D15 -> 12 | E31: =_xlfn.XLOOKUP(C31,SkillActive!A:A,SkillActive!B:B,,,) -> 旋风斩 | F31: =D31 -> 12 | G31: =_xlfn.XLOOKUP(C31,SkillActive!$A:$A,SkillActive!E:E,,0) -> 1
... A67: =C67*100+D67 -> 10100416 | B67: =_xlfn.XLOOKUP(C67,SkillActive!$A:$A,SkillActive!C:C,,0) -> 1|2|3|4|5|6|7 | C67: =C51+1 -> 101004 | D67: =D51 -> 16 | E67: =_xlfn.XLOOKUP(C67,SkillActive!A:A,SkillActive!B:B,,,) -> 混沌刺击 | F67: =D67 -> 16 | G67: =_xlfn.XLOOKUP(C67,SkillActive!$A:$A,SkillActive!E:E,,0) -> 1
A68: =C68*100+D68 -> 10200101 | B68: =_xlfn.XLOOKUP(C68,SkillActive!$A:$A,SkillActive!C:C,,0) -> 1|2|3|4|5|6|7 | C68: 102001 | D68: =D52 -> 1 | E68: 冥地喷涌 | F68: =D68 -> 1 | G68: 1
A69: =C69*100+D69 -> 10200102 | B69: =_xlfn.XLOOKUP(C69,SkillActive!$A:$A,SkillActive!C:C,,0) -> 1|2|3|4|5|6|7 | C69: 102001 | D69: =D53 -> 2 | E69: 冥地喷涌 | F69: =D69 -> 2 | G69: 2
A70: =C70*100+D70 -> 10200103 | B70: =_xlfn.XLOOKUP(C70,SkillActive!$A:$A,SkillActive!C:C,,0) -> 1|2|3|4|5|6|7 | C70: 102001 | D70: =D54 -> 3 | E70: 冥地喷涌 | F70: =D70 -> 3 | G70: 3
A71: =C71*100+D71 -> 10200104 | B71: =_xlfn.XLOOKUP(C71,SkillActive!$A:$A,SkillActive!C:C,,0) -> 1|2|3|4|5|6|7 | C71: 102001 | D71: =D55 -> 4 | E71: 冥地喷涌 | F71: =D71 -> 4 | G71: 4
A72: =C72*100+D72 -> 10200105 | B72: =_xlfn.XLOOKUP(C72,SkillActive!$A:$A,SkillActive!C:C,,0) -> 1|2|3|4|5|6|7 | C72: 102001 | D72: =D56 -> 5 | E72: 冥地喷涌 | F72: =D72 -> 5 | G72: 5
A73: =C73*100+D73 -> 10200106 | B73: =_xlfn.XLOOKUP(C73,SkillActive!$A:$A,SkillActive!C:C,,0) -> 1|2|3|4|5|6|7 | C73: 102001 | D73: =D57 -> 6 | E73: 冥地喷涌 | F73: =D73 -> 6 | G73: 6
A74: =C74*100+D74 -> 10200107 | B74: =_xlfn.XLOOKUP(C74,SkillActive!$A:$A,SkillActive!C:C,,0) -> 1|2|3|4|5|6|7 | C74: 102001 | D74: =D58 -> 7 | E74: 冥地喷涌 | F74: =D74 -> 7 | G74: 7
A75: =C75*100+D75 -> 10200108 | B75: =_xlfn.XLOOKUP(C75,SkillActive!$A:$A,SkillActive!C:C,,0) -> 1|2|3|4|5|6|7 | C75: 102001 | D75: =D59 -> 8 | E75: 冥地喷涌 | F75: =D75 -> 8 | G75: 8
A76: =C76*100+D76 -> 10200109 | B76: =_xlfn.XLOOKUP(C76,SkillActive!$A:$A,SkillActive!C:C,,0) -> 1|2|3|4|5|6|7 | C76: 102001 | D76: =D60 -> 9 | E76: 冥地喷涌 | F76: =D76 -> 9 | G76: 9
A77: =C77*100+D77 -> 10200110 | B77: =_xlfn.XLOOKUP(C77,SkillActive!$A:$A,SkillActive!C:C,,0) -> 1|2|3|4|5|6|7 | C77: 102001 | D77: =D61 -> 10 | E77: 冥地喷涌 | F77: =D77 -> 10 | G77: 10
...

Sheet SkillPassive
A1: 10030 | B1: (nouse)策划说明 | C1: 职业 | D1: 关联的节点id | E1: 技能界面位置 | F1: 节点大小 | G1: 图标 | H1: 名称 | I1: 描述 | J1: 词缀id | K1: 词缀值 | L1: 被动表id | M1: 提供属性-启用加属性
A2: id.p | B2: desc999 | C2: occupation | D2: linkPoint | E2: viewPos | F2: size | G2: icon | H2: name | I2: desc | J2: skillAffix | K2: affixValue | L2: stunt | M2: attr
A3: number | B3: string | C3: number | D3: numberArr | E3: numberArr | F3: number | G3: string | H3: string | I3: string | J3: numberArr | K3: object | L3: numberArr | M3: object
A4: 1000001 | B4: 通用-天赋1 | C4: 0 | D4: 1000002 | E4: 0|319.773 | F4: 1 | G4: talent/attribute/shengming | H4: 生命值 | I4: 生命值+5 | M4: [[10001,5]]
A5: 1000002 | B5: 通用-天赋2 | C5: 0 | D5: 1000001|1000003 | E5: 0|515.601 | F5: 1 | G5: talent/attribute/shengming | H5: 生命值 | I5: 生命值+5 | M5: [[10001,5]]
A6: 1000003 | B6: 通用-天赋3 | C6: 0 | D6: 1000002|1000004|1000008|1000013|1000018|1000023 | E6: 0|714.659 | F6: 1 | G6: talent/attribute/shengming | H6: 生命值 | I6: 生命值+5 | M6: [[10001,5]]
A7: 1000004 | B7: 通用-天赋4 | C7: 0 | D7: 1000003|1000005 | E7: 0|915.031 | F7: 1 | G7: talent/attribute/shengming | H7: 生命值 | I7: 生命值+5 | M7: [[10001,5]]
A8: 1000005 | B8: 通用-天赋5 | C8: 0 | D8: 1000004|1000006 | E8: 0|1115.499 | F8: 1 | G8: talent/attribute/shengming | H8: 生命值 | I8: 生命值+5 | M8: [[10001,5]]
A9: 1000006 | B9: 通用-天赋6 | C9: 0 | D9: 1000005|1000007 | E9: 0|1315.561 | F9: 1 | G9: talent/attribute/shengming | H9: 生命值 | I9: 生命值+5 | M9: [[10001,5]]
A10: 1000007 | B10: 通用-天赋7 | C10: 0 | D10: 1000006|1000012|1000017|1000022|1000027|1000028|1000032 | E10: 0|1659.996 | F10: 3 | G10: talent/attribute/tianfu | H10: 可选天赋 | I10: 激活一个可选天赋
A11: 1000008 | B11: 通用-天赋8 | C11: 0 | D11: 1000003|1000009 | E11: 153.553|654.916 | F11: 1 | G11: talent/attribute/bingkang | H11: 冰冷抗性 | I11: 冰冷抗性+2% | M11: [[10313,0.02]]
A12: 1000009 | B12: 通用-天赋9 | C12: 0 | D12: 1000008|1000010 | E12: 153.553|861.848 | F12: 1 | G12: talent/attribute/bingkang | H12: 冰冷抗性 | I12: 冰冷抗性+4% | M12: [[10313,0.04]]
A13: 1000010 | B13: 通用-天赋10 | C13: 0 | D13: 1000009|1000011 | E13: 153.553|1064.205 | F13: 2 | G13: talent/attribute/bingkang | H13: 冰冷抗性 | I13: 冰冷抗性+10% | M13: [[10313,0.1]]
A14: 1000011 | B14: 通用-天赋11 | C14: 0 | D14: 1000010|1000012 | E14: 153.553|1252.904 | F14: 1 | G14: talent/attribute/bingkang | H14: 冰冷抗性 | I14: 冰冷抗性+4% | M14: [[10313,0.04]]
A15: 1000012 | B15: 通用-天赋12 | C15: 0 | D15: 1000007|1000011 | E15: 153.553|1452.97 | F15: 1 | G15: talent/attribute/bingkang | H15: 冰冷抗性 | I15: 冰冷抗性+2% | M15: [[10313,0.02]]
A16: 1000013 | B16: 通用-天赋13 | C16: 0 | D16: 1000003|1000014 | E16: 307.106|654.916 | F16: 1 | G16: talent/attribute/huokang | H16: 火焰抗性 | I16: 火焰抗性+2% | M16: [[10312,0.02]]
A17: 1000014 | B17: 通用-天赋14 | C17: 0 | D17: 1000013|1000015 | E17: 307.106|861.848 | F17: 1 | G17: talent/attribute/huokang | H17: 火焰抗性 | I17: 火焰抗性+4% | M17: [[10312,0.04]]
A18: 1000015 | B18: 通用-天赋15 | C18: 0 | D18: 1000014|1000016 | E18: 307.106|1064.205 | F18: 2 | G18: talent/attribute/huokang | H18: 火焰抗性 | I18: 火焰抗性+10% | M18: [[10312,0.1]]
A19: 1000016 | B19: 通用-天赋16 | C19: 0 | D19: 1000015|1000017 | E19: 307.106|1252.904 | F19: 1 | G19: talent/attribute/huokang | H19: 火焰抗性 | I19: 火焰抗性+4% | M19: [[10312,0.04]]
A20: 1000017 | B20: 通用-天赋17 | C20: 0 | D20: 1000007|1000016 | E20: 307.106|1452.97 | F20: 1 | G20: talent/attribute/huokang | H20: 火焰抗性 | I20: 火焰抗性+2% | M20: [[10312,0.02]]
A21: 1000018 | B21: 通用-天赋18 | C21: 0 | D21: 1000003|1000019 | E21: -153.553|654.916 | F21: 1 | G21: talent/attribute/diankang | H21: 闪电抗性 | I21: 闪电抗性+2% | M21: [[10314,0.02]]
A22: 1000019 | B22: 通用-天赋19 | C22: 0 | D22: 1000018|1000020 | E22: -153.553|861.848 | F22: 1 | G22: talent/attribute/diankang | H22: 闪电抗性 | I22: 闪电抗性+4% | M22: [[10314,0.04]]
... A55: 1000052 | B55: 通用-天赋52 | C55: 0 | D55: 1000051|1000053 | E55: -307.106|2782.945 | F55: 1 | G55: talent/attribute/wushang | H55: 物理伤害 | I55: 物理伤害+10% | M55: [[10303,0.1]]
A56: 1000053 | B56: 通用-天赋53 | C56: 0 | D56: 1000032|1000037|1000042|1000047|1000052 | E56: 0|2945.874 | F56: 3 | G56: talent/attribute/tianfu | H56: 可选天赋 | I56: 激活一个可选天赋
A57: 1002001 | B57: 剑客-天赋1（旧版） | C57: 9 | D57: 1002002 | E57: 0|319.773 | F57: 1 | G57: talent/attribute/gongshang | H57: 攻击伤害 | I57: 攻击伤害+5% | M57: [[10301,0.05]]
A58: 1002002 | B58: 剑客-天赋2（旧版） | C58: 9 | D58: 1002001|1002003 | E58: 0|515.601 | F58: 1 | G58: talent/attribute/gongshang | H58: 攻击伤害 | I58: 攻击伤害+5% | M58: [[10301,0.05]]
A59: 1002003 | B59: 剑客-天赋3（旧版） | C59: 9 | D59: 1002002|1002004|1002008|1002013|1002018|1002023 | E59: 0|714.659 | F59: 1 | G59: talent/attribute/gongshang | H59: 攻击伤害 | I59: 攻击伤害+5% | M59: [[10301,0.05]]
A60: 1002004 | B60: 剑客-天赋4（旧版） | C60: 9 | D60: 1002003|1002005 | E60: 0|915.031 | F60: 1 | G60: talent/attribute/gongshang | H60: 攻击伤害 | I60: 攻击伤害+5% | M60: [[10301,0.05]]
A61: 1002005 | B61: 剑客-天赋5（旧版） | C61: 9 | D61: 1002004|1002006 | E61: 0|1115.499 | F61: 1 | G61: talent/attribute/gongshang | H61: 攻击伤害 | I61: 攻击伤害+5% | M61: [[10301,0.05]]
A62: 1002006 | B62: 剑客-天赋6（旧版） | C62: 9 | D62: 1002005|1002007 | E62: 0|1315.561 | F62: 1 | G62: talent/attribute/gongshang | H62: 攻击伤害 | I62: 攻击伤害+5% | M62: [[10301,0.05]]
A63: 1002007 | B63: 剑客-天赋7（旧版） | C63: 9 | D63: 1002006|1002012|1002017|1002022|1002027|1002028|1002032 | E63: 0|1659.996 | F63: 3 | G63: talent/attribute/tianfu | H63: 可选天赋 | I63: 激活一个可选天赋
A64: 1002008 | B64: 剑客-天赋8（旧版） | C64: 9 | D64: 1002003|1002009 | E64: 153.553|654.916 | F64: 1 | G64: talent/attribute/tousheshanghai | H64: 投射伤害 | I64: 投射物伤害+10% | J64: 40001
A65: 1002009 | B65: 剑客-天赋9（旧版） | C65: 9 | D65: 1002008|100201 | E65: 153.553|861.848 | F65: 1 | G65: talent/attribute/tousheshanghai | H65: 投射伤害 | I65: 投射物伤害+15% | J65: 40002
A66: 1002010 | B66: 剑客-天赋10（旧版） | C66: 9 | D66: 1002009|1002011 | E66: 153.553|1064.205 | F66: 2 | G66: talent/attribute/tousheshanghai | H66: 投射伤害 | I66: 投射物伤害+15% | J66: 40002
A67: 1002011 | B67: 剑客-天赋11（旧版） | C67: 9 | D67: 100201|1002012 | E67: 153.553|1252.904 | F67: 1 | G67: talent/attribute/tousheshanghai | H67: 投射伤害 | I67: 投射物伤害+15% | J67: 40002
A68: 1002012 | B68: 剑客-天赋12（旧版） | C68: 9 | D68: 1002007|1002011 | E68: 153.553|1452.97 | F68: 1 | G68: talent/attribute/tousheshanghai | H68: 投射伤害 | I68: 投射物伤害+10% | J68: 40001
A69: 1002013 | B69: 剑客-天赋13（旧版） | C69: 9 | D69: 1002003|1002014 | E69: 307.106|654.916 | F69: 1 | G69: talent/attribute/jinzhanshanghai | H69: 近战伤害 | I69: 近战伤害+10% | J69: 40003
A70: 1002014 | B70: 剑客-天赋14（旧版） | C70: 9 | D70: 1002013|1002015 | E70: 307.106|861.848 | F70: 1 | G70: talent/attribute/jinzhanshanghai | H70: 近战伤害 | I70: 近战伤害+15% | J70: 40004
A71: 1002015 | B71: 剑客-天赋15（旧版） | C71: 9 | D71: 1002014|1002016 | E71: 307.106|1064.205 | F71: 2 | G71: talent/attribute/jinzhanshanghai | H71: 近战伤害 | I71: 近战伤害+15% | J71: 40004
A72: 1002016 | B72: 剑客-天赋16（旧版） | C72: 9 | D72: 1002015|1002017 | E72: 307.106|1252.904 | F72: 1 | G72: talent/attribute/jinzhanshanghai | H72: 近战伤害 | I72: 近战伤害+15% | J72: 40004
...

Sheet SkillPassiveOptional
A1: 技能 | B1: (nouse)策划说明 | C1: 职业 | D1: 阶段-天赋大节点解锁 | E1: 图标 | F1: 名称 | G1: 描述 | H1: 词缀id | I1: 被动表id | J1: 提供属性-启用加属性
A2: id.p | B2: desc999 | C2: occupation | D2: stage | E2: icon | F2: name | G2: desc | H2: skillAffix | I2: stunt | J2: attr
A3: number | B3: string | C3: number | D3: number | E3: string | F3: string | G3: string | H3: numberArr | I3: numberArr | J3: object
A4: 2000001 | B4: 通用1-天赋1 | C4: 0 | D4: 1 | E4: talent/skill/dikang | F4: 抵抗 | G4: 每有1%混沌抗性，+1%元素异常状态抵抗 | H4: 10094
A5: 2000002 | B5: 通用1-天赋2 | C5: 0 | D5: 1 | E5: talent/skill/huoli | F5: 活力 | G5: 每秒回复25点生命值 | H5: 10093
A6: 2000003 | B6: 通用2-天赋1 | C6: 0 | D6: 2 | E6: talent/skill/leishen | F6: 雷神 | G6: 击中的闪电伤害额外提高25%，闪电伤害有30%几率附带触电累积 | H6: 10090
A7: 2000004 | B7: 通用2-天赋2 | C7: 0 | D7: 2 | E7: talent/skill/huoshen | F7: 火神 | G7: 击中的火焰伤害额外提高25%，火焰伤害使敌人的火焰抗性-20% | H7: 10091 | I7: 2140000100
A8: 2000005 | B8: 通用2-天赋3 | C8: 0 | D8: 2 | E8: talent/skill/bingshen | F8: 冰神 | G8: 击中的冰冷伤害额外提高25%，冰冻累积效果额外提高50% | H8: 10092
A9: 2002001 | B9: 剑客1-天赋1 | C9: 2 | D9: 1 | E9: talent/skill/cigu | F9: 刺骨寒意 | G9: 第一个技能的冻结积蓄值总增100%
A10: 2002002 | B10: 剑客1-天赋2 | C10: 2 | D10: 1 | E10: talent/skill/kuaigong | F10: 快攻 | G10: 第一个技能获得10级攻速增加效果
A11: 2002003 | B11: 剑客1-天赋3 | C11: 2 | D11: 1 | E11: talent/skill/liufeng | F11: 流风增击 | G11: 对于移动速度的增加或减少的20% 同时作用于额外攻击伤害，最多额外+30% 攻击伤害
A12: 2002004 | B12: 剑客1-天赋3 | C12: 2 | D12: 1 | E12: talent/skill/xinyan | F12: 心眼 | G12: 10秒内连续释放4次攻击技能时获得[心眼]状态\n[心眼]：攻击速度额外增加8%；技能范围额外增加8%，上限为3层，持续2秒 | I12: 2150000010
A13: 2002005 | B13: 剑客1-天赋3 | C13: 2 | D13: 1 | E13: talent/skill/baoxue | F13: 暴血 | G13: 每拥有1%的暴击率，就会增加2%的攻击伤害，最多增加200%的攻击伤害
A14: 2002006 | B14: 剑客1-天赋4 | C14: 2 | D14: 2 | E14: talent/skill/wuxin | F14: 无心则利刃 | G14: 心眼达到层数上限时，获得[巅峰]\n[巅峰]:向前斩击造成1000%的攻击物理伤害，冷却时间5秒 | I14: 2150000020
A15: 2002007 | B15: 剑客1-天赋4 | C15: 2 | D15: 2 | E15: talent/skill/jihan | F15: 极寒侵体 | G15: 被冻结敌人的元素抗性会降低40%，持续6秒 | I15: 2150000030
A16: 2002008 | B16: 剑客1-天赋4 | C16: 2 | D16: 2 | E16: talent/skill/kanpo | F16: 看破 | G16: 基础暴击率+8% | J16: [[10100,0.08]]

Sheet SkillSet
A1: 技能宝石槽位解锁对应技能等级
A2: slotUnlockLevel
A3: numberArr
A4: 1|4|6|9

Sheet SkillSect
A1: 秘籍id | B1: 序号 | C1: 品质id | D1: (nouse)策划说明 | E1: 解锁道具id | F1: 修炼道具id | G1: 升阶道具id | H1: 已拥有转化成材料 | I1: 图标 | J1: 名称 | K1: 描述 | L1: 词缀id | M1: 被动表id | N1: 提供属性-启用加属性 | O1: 每一阶提供属性 | P1: 提供属性-点击激活加属性 | Q1: 提供属性-图鉴激活加属性 | R1: 激活奖励 | S1: 启用秘籍战力值 | T1: 外显标签 | U1: 外显底图资源 | V1: 未获得时是否显示
A2: id.p | B2: num.p | C2: quality | D2: desc999 | E2: unlockItem | F2: proficiencyItem | G2: breakItem | H2: trans | I2: icon | J2: name | K2: desc | L2: skillAffix | M2: stunt | N2: attr | O2: breakAttr | P2: attr1 | Q2: attr2 | R2: reward | S2: power | T2: type | U2: frameRes | V2: isShow
A3: number | B3: number | C3: number | D3: string | E3: number | F3: number | G3: number2 | H3: object | I3: string | J3: string | K3: string | L3: number2 | M3: numberArr | N3: object | O3: object | P3: object | Q3: object | R3: object | S3: number | T3: stringArr | U3: stringArr | V3: number
A4: 1011 | B4: 1 | C4: 3 | D4: 普通攻击 | E4: 101101 | F4: 101110 | H4: [[101110,300]] | I4: skill/sect/101101 | J4: 崩裂击 | K4: 角色暴击率提高<color=be7013>5%</color> | N4: [[3014,0.05]] | O4: [[3059,0.02]] | P4: [[3009,0.01],[3010,0.01],[3011,0.01]] | Q4: [[3001,1],[3002,1],[3003,100]] | R4: [[103,10]] | S4: 1000 | T4: 增益 | U4: skill_affix/hong | V4: 1
A5: 1011 | B5: 2 | C5: 4 | D5: 普通攻击 | E5: 101102 | F5: 101110 | H5: [[101110,600]] | I5: skill/sect/101102 | J5: 崩裂击 | K5: 击碎强化为血蚀击碎，平均每秒对敌人造成<color=be7013>7</color>%物理伤害与<color=be7013>40</color>%创伤伤害 | L5: 120112000 | N5: [[3014,0.05]] | O5: [[3059,0.02]] | P5: [[3009,0.02],[3010,0.02],[3011,0.02]] | Q5: [[3001,5],[3002,1],[3003,500]] | R5: [[103,10]] | S5: 3000 | T5: 创伤|增益 | U5: skill_affix/huang|skill_affix/hong | V5: 1
A6: 1011 | B6: 3 | C6: 6 | D6: 普通攻击 | E6: 101103 | F6: 101110 | H6: [[101110,900]] | I6: skill/sect/101103 | J6: 崩裂击 | K6: 角色最终减伤提高<color=be7013>5%</color> | L6: 120112000 | N6: [[3014,0.05],[3060,0.05]] | O6: [[3059,0.02]] | P6: [[3009,0.03],[3010,0.03],[3011,0.03]] | Q6: [[3001,10],[3002,2],[3003,1000]] | R6: [[103,10]] | S6: 6000 | T6: 创伤|增益 | U6: skill_affix/huang|skill_affix/hong | V6: 1
A7: 1011 | B7: 4 | C7: 8 | D7: 普通攻击 | E7: 101104 | F7: 101110 | G7: 101120 | H7: [[101120,1]] | I7: skill/sect/101104 | J7: 崩裂击 | K7: 击碎命中敌人有<color=be7013>20%</color>概率施加<u color=4169E1 size=2><a href=30018>重伤</a></u>，持续<color=be7013>3</color>秒 | L7: 120114000 | M7: 120114000 | N7: [[3014,0.05],[3060,0.05]] | O7: [[3059,0.02]] | P7: [[3009,0.04],[3010,0.04],[3011,0.04]] | Q7: [[3001,50],[3002,10],[3003,5000]] | R7: [[103,10]] | S7: 10000 | T7: 创伤|增益 | U7: skill_affix/huang|skill_affix/hong | V7: 1
A8: 5011 | B8: 1 | C8: 3 | D8: 普通攻击 | E8: 101201 | F8: 101210 | H8: [[101210,300]] | I8: skill/sect/101201 | J8: 癫狂击 | K8: 释放击碎额外恢复<color=be7013>1</color>点战意 | M8: 120121000 | O8: [[3059,0.02]] | P8: [[3009,0.01],[3010,0.01],[3011,0.01]] | Q8: [[3001,1],[3002,1],[3003,100]] | R8: [[103,10]] | S8: 1000 | T8: 充能 | U8: skill_affix/hong | V8: 1
A9: 5011 | B9: 2 | C9: 4 | D9: 普通攻击 | E9: 101202 | F9: 101210 | H9: [[101210,600]] | I9: skill/sect/101202 | J9: 癫狂击 | K9: 释放击碎有20%概率获得<u color=4169E1 size=2><a href=30019>狂热</a></u>，持续<color=be7013>3</color>秒 | M9: 120121000|120122000 | O9: [[3059,0.02]] | P9: [[3009,0.02],[3010,0.02],[3011,0.02]] | Q9: [[3001,5],[3002,1],[3003,500]] | R9: [[103,10]] | S9: 3000 | T9: 追击|充能 | U9: skill_affix/huang|skill_affix/hong | V9: 1
A10: 5011 | B10: 3 | C10: 6 | D10: 普通攻击 | E10: 101203 | F10: 101210 | H10: [[101210,900]] | I10: skill/sect/101203 | J10: 癫狂击 | K10: 角色战意充能提高<color=be7013>17.5%</color> | M10: 120121000|120122000 | N10: [[3005,0.175]] | O10: [[3059,0.02]] | P10: [[3009,0.03],[3010,0.03],[3011,0.03]] | Q10: [[3001,10],[3002,2],[3003,1000]] | R10: [[103,10]] | S10: 6000 | T10: 追击|充能 | U10: skill_affix/huang|skill_affix/hong | V10: 1
A11: 1012 | B11: 4 | C11: 8 | D11: 普通攻击 | E11: 101204 | F11: 101210 | G11: 101220 | H11: [[101220,1]] | I11: skill/sect/101204 | J11: 癫狂击 | K11: <u color=4169E1 size=2><a href=30019>狂热</a></u>强化为<u color=4169E1 size=2><a href=30020>极端狂热</a></u>，物理伤害加成提高至<color=be7013>10%</color> | M11: 120121000|120124000 | N11: [[3005,0.175]] | O11: [[3059,0.02]] | P11: [[3009,0.04],[3010,0.04],[3011,0.04]] | Q11: [[3001,50],[3002,10],[3003,5000]] | R11: [[103,10]] | S11: 10000 | T11: 追击|充能 | U11: skill_affix/huang|skill_affix/hong | V11: 1
A12: 1012 | B12: =B8 -> 1 | C12: =C8 -> 3 | D12: =D8 -> 普通攻击 | E12: =E8+100 -> 101301 | F12: =F8+100 -> 101310 | H12: ="[["&F12&",300]]" -> [[101310,300]] | I12: ="skill/sect/"&E12 -> skill/sect/101301 | J12: 雷霆击 | K12: 角色魔法增伤提高<color=be7013>5%</color> | N12: [[3023,0.05]] | O12: [[3059,0.02]] | P12: [[3009,0.01],[3010,0.01],[3011,0.01]] | Q12: [[3001,1],[3002,1],[3003,100]] | R12: =R8 -> [[103,10]] | S12: =S4 -> 1000 | T12: 增益 | U12: skill_affix/hong | V12: 0
A13: 1012 | B13: =B9 -> 2 | C13: =C9 -> 4 | D13: =D9 -> 普通攻击 | E13: =E9+100 -> 101302 | F13: =F9+100 -> 101310 | H13: ="[["&F13&",600]]" -> [[101310,600]] | I13: ="skill/sect/"&E13 -> skill/sect/101302 | J13: 雷霆击 | K13: 普攻命中<color=be7013>20%</color>概率给敌人施加雷电之种，延迟2秒后爆炸造成<color=be7013>31%</color>魔法伤害 | L13: 120132000 | M13: 120132000 | N13: [[3023,0.05]] | O13: [[3059,0.02]] | P13: [[3009,0.02],[3010,0.02],[3011,0.02]] | Q13: [[3001,5],[3002,1],[3003,500]] | R13: =R9 -> [[103,10]] | S13: =S5 -> 3000 | T13: 引爆|增益 | U13: skill_affix/huang|skill_affix/hong | V13: 0
A14: 1012 | B14: =B10 -> 3 | C14: =C10 -> 6 | D14: =D10 -> 普通攻击 | E14: =E10+100 -> 101303 | F14: =F10+100 -> 101310 | H14: ="[["&F14&",900]]" -> [[101310,900]] | I14: ="skill/sect/"&E14 -> skill/sect/101303 | J14: 雷霆击 | K14: 角色最终减伤提高<color=be7013>5%</color> | L14: 120132000 | M14: 120132000 | N14: [[3023,0.05],[3060,0.05]] | O14: [[3059,0.02]] | P14: [[3009,0.03],[3010,0.03],[3011,0.03]] | Q14: [[3001,10],[3002,2],[3003,1000]] | R14: =R10 -> [[103,10]] | S14: =S6 -> 6000 | T14: 引爆|增益 | U14: skill_affix/huang|skill_affix/hong | V14: 0
A15: =A11+1 -> 1013 | B15: =B11 -> 4 | C15: =C11 -> 8 | D15: =D11 -> 普通攻击 | E15: =E11+100 -> 101304 | F15: =F11+100 -> 101310 | G15: =G11+100 -> 101320 | H15: ="[["&G15&",1]]" -> [[101320,1]] | I15: ="skill/sect/"&E15 -> skill/sect/101304 | J15: 雷霆击 | K15: 提高雷电之种施加概率至<color=be7013>30%</color>，爆炸伤害提高至<color=be7013>42%</color> | L15: 120132000 | M15: 120134000 | N15: [[3023,0.05],[3060,0.05]] | O15: [[3059,0.02]] | P15: [[3009,0.04],[3010,0.04],[3011,0.04]] | Q15: [[3001,50],[3002,10],[3003,5000]] | R15: =R11 -> [[103,10]] | S15: =S7 -> 10000 | T15: 引爆|增益 | U15: skill_affix/huang|skill_affix/hong | V15: 0
A16: 1021 | B16: 1 | C16: 3 | D16: 核心技能 | E16: 102101 | F16: 102110 | H16: [[102110,300]] | I16: skill/sect/102101 | J16: 熔血重斩 | K16: 角色创伤伤害提高<color=be7013>7.5%</color> | N16: [[3033,0.075]] | O16: [[3059,0.02]] | P16: [[3009,0.01],[3010,0.01],[3011,0.01]] | Q16: [[3001,1],[3002,1],[3003,100]] | R16: [[103,10]] | S16: 2000 | T16: 创伤 | U16: skill_affix/huang | V16: 1
A17: 1021 | B17: 2 | C17: 4 | D17: 核心技能 | E17: 102102 | F17: 102110 | H17: [[102110,600]] | I17: skill/sect/102102 | J17: 熔血重斩 | K17: 裂地斩击强化为血焰斩击，命中时对目标造成<color=be7013>73%</color>物理伤害与<color=be7013>442%</color>创伤伤害 | L17: 120212000 | N17: [[3033,0.075]] | O17: [[3059,0.02]] | P17: [[3009,0.02],[3010,0.02],[3011,0.02]] | Q17: [[3001,5],[3002,1],[3003,500]] | R17: [[103,10]] | S17: 5000 | T17: 创伤|减益 | U17: skill_affix/huang|skill_affix/qing | V17: 1
A18: 1021 | B18: 3 | C18: 6 | D18: 核心技能 | E18: 102103 | F18: 102110 | H18: [[102110,900]] | I18: skill/sect/102103 | J18: 熔血重斩 | K18: 释放核心技能时为自身施加<color=be7013>1</color>层<u color=4169E1 size=2><a href=30021>血印</a></u>，最多<color=be7013>4</color>层 | L18: 120212000 | M18: 120213000 | N18: [[3033,0.075]] | O18: [[3059,0.02]] | P18: [[3009,0.03],[3010,0.03],[3011,0.03]] | Q18: [[3001,10],[3002,2],[3003,1000]] | R18: [[103,10]] | S18: 10000 | T18: 创伤|减益 | U18: skill_affix/huang|skill_affix/qing | V18: 1
A19: 1021 | B19: 4 | C19: 8 | D19: 核心技能 | E19: 102104 | F19: 102110 | G19: 102120 | H19: [[102120,1]] | I19: skill/sect/102104 | J19: 熔血重斩 | K19: 血焰爆裂留下持续<color=be7013>5</color>秒的血池，对周围每秒造成<color=be7013>13%</color>物理伤害与<color=be7013>79%</color>创伤伤害 | L19: 120214000 | M19: 120213000 | N19: [[3033,0.075]] | O19: [[3059,0.02]] | P19: [[3009,0.04],[3010,0.04],[3011,0.04]] | Q19: [[3001,50],[3002,10],[3003,5000]] | R19: [[103,10]] | S19: 20000 | T19: 创伤|减益 | U19: skill_affix/huang|skill_affix/qing | V19: 1
A20: 1022 | B20: 1 | C20: 3 | D20: 核心技能 | E20: 102201 | F20: 102210 | H20: [[102210,300]] | I20: skill/sect/102201 | J20: 燃火重斩 | K20: 裂地斩击耗能降低<color=be7013>6</color>点 | L20: 120221000 | O20: [[3059,0.02]] | P20: [[3009,0.01],[3010,0.01],[3011,0.01]] | Q20: [[3001,1],[3002,1],[3003,100]] | R20: [[103,10]] | S20: 2000 | T20: 降耗 | U20: skill_affix/hong | V20: 1
A21: 1022 | B21: 2 | C21: 4 | D21: 核心技能 | E21: 102202 | F21: 102210 | H21: [[102210,600]] | I21: skill/sect/102202 | J21: 燃火重斩 | K21: 裂地斩击伤害提升至<color=be7013>252%</color>物理伤害，同时每次释放裂地斩击时在周围随机敌人处生成火焰喷流造成<color=be7013>111%</color>魔法伤害 | L21: 120222000 | O21: [[3059,0.02]] | P21: [[3009,0.02],[3010,0.02],[3011,0.02]] | Q21: [[3001,5],[3002,1],[3003,500]] | R21: [[103,10]] | S21: 5000 | T21: 追击|降耗 | U21: skill_affix/huang|skill_affix/hong | V21: 1
A22: 1022 | B22: 3 | C22: 6 | D22: 核心技能 | E22: 102203 | F22: 102210 | H22: [[102210,900]] | I22: skill/sect/102203 | J22: 燃火重斩 | K22: 裂地斩击伤害提高<color=be7013>40%</color> | L22: 120222000 | N22: [[3097,0.4]] | O22: [[3059,0.02]] | P22: [[3009,0.03],[3010,0.03],[3011,0.03]] | Q22: [[3001,10],[3002,2],[3003,1000]] | R22: [[103,10]] | S22: 10000 | T22: 追击|降耗 | U22: skill_affix/huang|skill_affix/hong | V22: 1
A23: 1022 | B23: 4 | C23: 8 | D23: 核心技能 | E23: 102204 | F23: 102210 | G23: 102220 | H23: [[102220,1]] | I23: skill/sect/102204 | J23: 燃火重斩 | K23: 裂地斩击伤害提升至<color=be7013>485%</color>物理伤害，火焰喷流强化为熔岩喷发对更大范围敌人造成<color=be7013>205%</color>魔法伤害 | L23: 120224000 | N23: [[3097,0.4]] | O23: [[3059,0.02]] | P23: [[3009,0.04],[3010,0.04],[3011,0.04]] | Q23: [[3001,50],[3002,10],[3003,5000]] | R23: [[103,10]] | S23: 20000 | T23: 追击|降耗 | U23: skill_affix/huang|skill_affix/hong | V23: 1
A24: =A20+1 -> 1023 | B24: =B20 -> 1 | C24: =C20 -> 3 | D24: =D20 -> 核心技能 | E24: =E20+100 -> 102301 | F24: =F20+100 -> 102310 | H24: ="[["&F24&",300]]" -> [[102310,300]] | I24: ="skill/sect/"&E24 -> skill/sect/102301 | J24: 怒雷横扫 | K24: 角色暴击率提高<color=be7013>5%</color> | N24: [[3014,0.05]] | O24: [[3059,0.02]] | P24: [[3009,0.01],[3010,0.01],[3011,0.01]] | Q24: [[3001,1],[3002,1],[3003,100]] | R24: =R20 -> [[103,10]] | S24: =S16 -> 2000 | T24: 暴击 | U24: skill_affix/hong | V24: 0
A25: =A21+1 -> 1023 | B25: =B21 -> 2 | C25: =C21 -> 4 | D25: =D21 -> 核心技能 | E25: =E21+100 -> 102302 | F25: =F21+100 -> 102310 | H25: ="[["&F25&",600]]" -> [[102310,600]] | I25: ="skill/sect/"&E25 -> skill/sect/102302 | J25: 怒雷横扫 | K25: 释放核心技能给自身施加雷电领域，雷电领域持续5秒，对范围内敌人每秒造成<color=be7013>34%</color>魔法伤害并施加<u color=4169E1 size=2><a href=30037>感电</a></u> | L25: 120232000 | M25: 120232000 | N25: [[3014,0.05]] | O25: [[3059,0.02]] | P25: [[3009,0.02],[3010,0.02],[3011,0.02]] | Q25: [[3001,5],[3002,1],[3003,500]] | R25: =R21 -> [[103,10]] | S25: =S17 -> 5000 | T25: 引爆|暴击 | U25: skill_affix/huang|skill_affix/hong | V25: 0
A26: =A22+1 -> 1023 | B26: =B22 -> 3 | C26: =C22 -> 6 | D26: =D22 -> 核心技能 | E26: =E22+100 -> 102303 | F26: =F22+100 -> 102310 | H26: ="[["&F26&",900]]" -> [[102310,900]] | I26: ="skill/sect/"&E26 -> skill/sect/102303 | J26: 怒雷横扫 | K26: 角色暴击伤害提高<color=be7013>30%</color> | L26: 120232000 | M26: 120232000 | N26: [[3014,0.05],[3015,0.3]] | O26: [[3059,0.02]] | P26: [[3009,0.03],[3010,0.03],[3011,0.03]] | Q26: [[3001,10],[3002,2],[3003,1000]] | R26: =R22 -> [[103,10]] | S26: =S18 -> 10000 | T26: 引爆|暴击 | U26: skill_affix/huang|skill_affix/hong | V26: 0
A27: =A23+1 -> 1023 | B27: =B23 -> 4 | C27: =C23 -> 8 | D27: =D23 -> 核心技能 | E27: =E23+100 -> 102304 | F27: =F23+100 -> 102310 | G27: =G23+100 -> 102320 | H27: ="[["&G27&",1]]" -> [[102320,1]] | I27: ="skill/sect/"&E27 -> skill/sect/102304 | J27: 怒雷横扫 | K27: 雷电领域获得强化，每秒造成<color=be7013>60%</color>魔法伤害，持续时间延长至8秒 | L27: 120232000 | M27: 120234000 | N27: [[3014,0.05],[3015,0.3]] | O27: [[3059,0.02]] | P27: [[3009,0.04],[3010,0.04],[3011,0.04]] | Q27: [[3001,50],[3002,10],[3003,5000]] | R27: =R23 -> [[103,10]] | S27: =S19 -> 20000 | T27: 引爆|暴击 | U27: skill_affix/huang|skill_affix/hong | V27: 0
A28: 1031 | B28: 1 | C28: 3 | D28: 位移技能 | E28: 103101 | F28: 103110 | H28: [[103110,300]] | I28: skill/sect/103101 | J28: 压制冲刺 | K28: 狂野冲锋冷却时间缩减<color=be7013>15%</color> | N28: [[3249,0.15]] | O28: [[3059,0.02]] | P28: [[3009,0.01],[3010,0.01],[3011,0.01]] | Q28: [[3001,1],[3002,1],[3003,100]] | R28: [[103,10]] | S28: 1000 | T28: 位移 | U28: skill_affix/lv | V28: 1
A29: 1031 | B29: 2 | C29: 4 | D29: 位移技能 | E29: 103102 | F29: 103110 | H29: [[103110,600]] | I29: skill/sect/103102 | J29: 压制冲刺 | K29: 狂野冲锋结束后额外进行一段上挑攻击，造成<color=be7013>233%</color>物理伤害并附带<color=be7013>0.5</color>秒<u color=4169E1 size=2><a href=30022>眩晕</a></u> | L29: 120312000 | N29: [[3249,0.15]] | O29: [[3059,0.02]] | P29: [[3009,0.02],[3010,0.02],[3011,0.02]] | Q29: [[3001,5],[3002,1],[3003,500]] | R29: [[103,10]] | S29: 3000 | T29: 位移|控制 | U29: skill_affix/lv|skill_affix/zi | V29: 1
A30: 1031 | B30: 3 | C30: 6 | D30: 位移技能 | E30: 103103 | F30: 103110 | H30: [[103110,900]] | I30: skill/sect/103103 | J30: 压制冲刺 | K30: 角色最终增伤提高<color=be7013>5%</color> | L30: 120312000 | N30: [[3249,0.15],[3059,0.05]] | O30: [[3059,0.02]] | P30: [[3009,0.03],[3010,0.03],[3011,0.03]] | Q30: [[3001,10],[3002,2],[3003,1000]] | R30: [[103,10]] | S30: 6000 | T30: 位移|控制 | U30: skill_affix/lv|skill_affix/zi | V30: 1
A31: 1031 | B31: 4 | C31: 8 | D31: 位移技能 | E31: 103104 | F31: 103110 | G31: 103120 | H31: [[103120,1]] | I31: skill/sect/103104 | J31: 压制冲刺 | K31: 狂野冲锋上挑伤害提高至<color=be7013>300</color>%物理伤害，且<u color=4169E1 size=2><a href=30022>眩晕</a></u>延长至<color=be7013>1.5</color>秒 | L31: 120314000 | N31: [[3249,0.15],[3059,0.05]] | O31: [[3059,0.02]] | P31: [[3009,0.04],[3010,0.04],[3011,0.04]] | Q31: [[3001,50],[3002,10],[3003,5000]] | R31: [[103,10]] | S31: 10000 | T31: 位移|控制 | U31: skill_affix/lv|skill_affix/zi | V31: 1
A32: 1032 | B32: 1 | C32: 3 | D32: 位移技能 | E32: 103201 | F32: 103210 | H32: [[103210,300]] | I32: skill/sect/103201 | J32: 复仇冲锋 | K32: 角色反击率提高<color=be7013>5%</color> | N32: [[3025,0.05]] | O32: [[3059,0.02]] | P32: [[3009,0.01],[3010,0.01],[3011,0.01]] | Q32: [[3001,1],[3002,1],[3003,100]] | R32: [[103,10]] | S32: 1000 | T32: 反击 | U32: skill_affix/hong | V32: 1
A33: 1032 | B33: 2 | C33: 4 | D33: 位移技能 | E33: 103202 | F33: 103210 | H33: [[103210,600]] | I33: skill/sect/103202 | J33: 复仇冲锋 | K33: 狂野冲锋结束时，若面前还有敌人则追加快速冲锋造成<color=be7013>209%</color>物理伤害并给自身施加<color=be7013>15%</color>最大生命护盾 | L33: 120322000 | N33: [[3025,0.05]] | O33: [[3059,0.02]] | P33: [[3009,0.02],[3010,0.02],[3011,0.02]] | Q33: [[3001,5],[3002,1],[3003,500]] | R33: [[103,10]] | S33: 3000 | T33: 反击|护盾 | U33: skill_affix/hong|skill_affix/lan | V33: 1
A34: 1032 | B34: 3 | C34: 6 | D34: 位移技能 | E34: 103203 | F34: 103210 | H34: [[103210,900]] | I34: skill/sect/103203 | J34: 复仇冲锋 | K34: 角色反击伤害提高<color=be7013>10%</color> | L34: 120322000 | N34: [[3025,0.05],[3027,0.1]] | O34: [[3059,0.02]] | P34: [[3009,0.03],[3010,0.03],[3011,0.03]] | Q34: [[3001,10],[3002,2],[3003,1000]] | R34: [[103,10]] | S34: 6000 | T34: 反击|护盾 | U34: skill_affix/hong|skill_affix/lan | V34: 1
A35: 1032 | B35: 4 | C35: 8 | D35: 位移技能 | E35: 103204 | F35: 103210 | G35: 103220 | H35: [[103220,1]] | I35: skill/sect/103204 | J35: 复仇冲锋 | K35: 狂野冲锋每命中一个敌人，给自身施加<u color=4169E1 size=2><a href=30023>无双</a></u>，上限<color=be7013>5</color>层，持续<color=be7013>10</color>秒 | L35: 120322000 | M35: 120324000 | N35: [[3025,0.05],[3027,0.1]] | O35: [[3059,0.02]] | P35: [[3009,0.04],[3010,0.04],[3011,0.04]] | Q35: [[3001,50],[3002,10],[3003,5000]] | R35: [[103,10]] | S35: 10000 | T35: 反击|护盾 | U35: skill_affix/hong|skill_affix/lan | V35: 1
A36: =A32+1 -> 1033 | B36: =B32 -> 1 | C36: =C32 -> 3 | D36: =D32 -> 位移技能 | E36: =E32+100 -> 103301 | F36: =F32+100 -> 103310 | H36: ="[["&F36&",300]]" -> [[103310,300]] | I36: ="skill/sect/"&E36 -> skill/sect/103301 | J36: 震慑冲锋 | K36: 角色掌控技能增伤提高<color=be7013>25%</color> | N36: [[3041,0.25]] | O36: [[3059,0.02]] | P36: [[3009,0.01],[3010,0.01],[3011,0.01]] | Q36: [[3001,1],[3002,1],[3003,100]] | R36: =R32 -> [[103,10]] | S36: =S28 -> 1000 | T36: 位移 | U36: skill_affix/lv | V36: 0
A37: =A33+1 -> 1033 | B37: =B33 -> 2 | C37: =C33 -> 4 | D37: =D33 -> 位移技能 | E37: =E33+100 -> 103302 | F37: =F33+100 -> 103310 | H37: ="[["&F37&",600]]" -> [[103310,600]] | I37: ="skill/sect/"&E37 -> skill/sect/103302 | J37: 震慑冲锋 | K37: 冲锋命中对敌人施加<u color=4169E1 size=2><a href=30038>电压</a></u> | L37: 120332000 | M37: 120332001 | N37: [[3041,0.25]] | O37: [[3059,0.02]] | P37: [[3009,0.02],[3010,0.02],[3011,0.02]] | Q37: [[3001,5],[3002,1],[3003,500]] | R37: =R33 -> [[103,10]] | S37: =S29 -> 3000 | T37: 位移|控制 | U37: skill_affix/lv|skill_affix/zi | V37: 0
A38: =A34+1 -> 1033 | B38: =B34 -> 3 | C38: =C34 -> 6 | D38: =D34 -> 位移技能 | E38: =E34+100 -> 103303 | F38: =F34+100 -> 103310 | H38: ="[["&F38&",900]]" -> [[103310,900]] | I38: ="skill/sect/"&E38 -> skill/sect/103303 | J38: 震慑冲锋 | K38: 角色战意充能提高<color=be7013>5%</color> | L38: 120332000 | M38: 120332001 | N38: [[3041,0.25],[3005,0.05]] | O38: [[3059,0.02]] | P38: [[3009,0.03],[3010,0.03],[3011,0.03]] | Q38: [[3001,10],[3002,2],[3003,1000]] | R38: =R34 -> [[103,10]] | S38: =S30 -> 6000 | T38: 位移|控制 | U38: skill_affix/lv|skill_affix/zi | V38: 0
A39: =A35+1 -> 1033 | B39: =B35 -> 4 | C39: =C35 -> 8 | D39: =D35 -> 位移技能 | E39: =E35+100 -> 103304 | F39: =F35+100 -> 103310 | G39: =G35+100 -> 103320 | H39: ="[["&G39&",1]]" -> [[103320,1]] | I39: ="skill/sect/"&E39 -> skill/sect/103304 | J39: 震慑冲锋 | K39: 冲锋命中对敌人施加<u color=4169E1 size=2><a href=30039>强力电压</a></u> | L39: 120332000 | M39: 120334001 | N39: [[3041,0.25],[3005,0.05]] | O39: [[3059,0.02]] | P39: [[3009,0.04],[3010,0.04],[3011,0.04]] | Q39: [[3001,50],[3002,10],[3003,5000]] | R39: =R35 -> [[103,10]] | S39: =S31 -> 10000 | T39: 位移|控制 | U39: skill_affix/lv|skill_affix/zi | V39: 0
A40: 1041 | B40: 1 | C40: 3 | D40: BUFF技能 | E40: 104101 | F40: 104110 | H40: [[104110,300]] | I40: skill/sect/104101 | J40: 无畏之躯 | K40: 战斗怒火冷却时间缩减<color=be7013>15%</color> | N40: [[3256,0.15]] | O40: [[3059,0.02]] | P40: [[3009,0.01],[3010,0.01],[3011,0.01]] | Q40: [[3001,1],[3002,1],[3003,100]] | R40: [[103,10]] | S40: 1000 | T40: 增益 | U40: skill_affix/hong | V40: 1
...

Sheet SkillSelectBox
A1: id | B1: 备注(nouse) | C1: 自选箱类型 | D1: 自选箱等级 | E1: 是否可合成 | F1: 原料数量 | G1: 合成成功概率 | H1: 合成后道具
A2: id.p | B2: desc999 | C2: type | D2: level | E2: ifSynthesis | F2: materialNum | G2: synthesisProb | H2: synthesisItem
A3: number | B3: string | C3: number | D3: number | E3: number | F3: number2 | G3: number2 | H3: object
A4: 1001 | B4: 技能书自选箱等级1 | C4: 1 | D4: 1 | E4: 1 | F4: 2 | G4: 0.5 | H4: [[1002,1]]
A5: 1002 | B5: 技能书自选箱等级2 | C5: 1 | D5: 2 | E5: 1 | F5: 2 | G5: 0.46 | H5: [[1003,1]]
A6: 1003 | B6: 技能书自选箱等级3 | C6: 1 | D6: 3 | E6: 1 | F6: 2 | G6: 0.42 | H6: [[1004,1]]
A7: 1004 | B7: 技能书自选箱等级4 | C7: 1 | D7: 4 | E7: 1 | F7: 2 | G7: 0.38 | H7: [[1005,1]]
A8: 1005 | B8: 技能书自选箱等级5 | C8: 1 | D8: 5 | E8: 1 | F8: 2 | G8: 0.34 | H8: [[1006,1]]
A9: 1006 | B9: 技能书自选箱等级6 | C9: 1 | D9: 6 | E9: 1 | F9: 2 | G9: 0.3 | H9: [[1007,1]]
A10: 1007 | B10: 技能书自选箱等级7 | C10: 1 | D10: 7 | E10: 1 | F10: 2 | G10: 0.26 | H10: [[1008,1]]
A11: 1008 | B11: 技能书自选箱等级8 | C11: 1 | D11: 8 | E11: 1 | F11: 2 | G11: 0.22 | H11: [[1009,1]]
A12: 1009 | B12: 技能书自选箱等级9 | C12: 1 | D12: 9 | E12: 1 | F12: 2 | G12: 0.18 | H12: [[1010,1]]
A13: 1010 | B13: 技能书自选箱等级10 | C13: 1 | D13: 10 | E13: 1 | F13: 2 | G13: 0.1 | H13: [[1011,1]]
A14: 1011 | B14: 技能书自选箱等级11 | C14: 1 | D14: 11 | E14: 1 | F14: 2 | G14: 0.05 | H14: [[1012,1]]
A15: 1012 | B15: 技能书自选箱等级12 | C15: 1 | D15: 12 | E15: 1 | F15: 2 | G15: 0.01 | H15: [[1013,1]]
A16: 1013 | B16: 技能书自选箱等级13 | C16: 1 | D16: 13 | E16: 1 | F16: 2
A17: 1014 | B17: 技能书自选箱等级14 | C17: 1 | D17: 14 | E17: 1 | F17: 2
A18: 1015 | B18: 技能书自选箱等级15 | C18: 1 | D18: 15 | E18: 1 | F18: 2
A19: 1016 | B19: 技能书自选箱等级16 | C19: 1 | D19: 16 | E19: 0
A20: 1101 | B20: 宝石自选箱等级1 | C20: 2 | D20: 1 | E20: 0
A21: 1102 | B21: 宝石自选箱等级2 | C21: 2 | D21: 2 | E21: 0
A22: 1103 | B22: 宝石自选箱等级3 | C22: 2 | D22: 3 | E22: 0
A23: 1104 | B23: 宝石自选箱等级4 | C23: 2 | D23: 4 | E23: 0
A24: 1105 | B24: 宝石自选箱等级5 | C24: 2 | D24: 5 | E24: 0
