Workbook

Sheet EquipType
A1: ID | B1: (nouse)装备部位 | C1: 装备部位 | D1: 职业限制 | E1: (nouse)种类号 | F1: 前缀词条池 | G1: 后缀词条池 | H1: 装备分类 | I1: 武器关联roleId
A2: id.p | B2: desc999 | C2: site | D2: career | E2: desc997 | F2: modifier1Pool | G2: modifier2Pool | H2: typeName | I2: roleId
A3: number | B3: string | C3: number | D3: number | E3: string | F3: number | G3: number | H3: string | I3: number2
A4: =(10+C4)*100&E4 -> 11001 | B4: 法杖 | C4: 1 | D4: 0 | E4: 1 | F4: 110011 | G4: 110012 | H4: 法杖 | I4: 9
A5: =(10+C5)*100&E5 -> 11002 | B5: 长剑 | C5: 1 | D5: 0 | E5: 2 | F5: 110021 | G5: 110022 | H5: 长剑 | I5: 6
A6: =(10+C6)*100&E6 -> 11003 | B6: 魔典 | C6: 1 | D6: 0 | E6: 3 | F6: 110021 | G6: 110022 | H6: 魔典 | I6: 12
A7: =(10+C7)*100&E7 -> 12001 | B7: 头盔 | C7: 2 | D7: 0 | E7: 1 | F7: 120011 | G7: 120012 | H7: 头盔
A8: =(10+C8)*100&E8 -> 13001 | B8: 胸甲 | C8: 3 | D8: 0 | E8: 1 | F8: 130011 | G8: 130012 | H8: 胸甲
A9: =(10+C9)*100&E9 -> 14001 | B9: 裤子 | C9: 4 | D9: 0 | E9: 1 | F9: 140011 | G9: 140012 | H9: 裤子
A10: =(10+C10)*100&E10 -> 15001 | B10: 鞋子 | C10: 5 | D10: 0 | E10: 1 | F10: 150011 | G10: 150012 | H10: 鞋子
A11: =(10+C11)*100&E11 -> 16001 | B11: 手套 | C11: 6 | D11: 0 | E11: 1 | F11: 160011 | G11: 160012 | H11: 手套
A12: =(10+C12)*100&E12 -> 17001 | B12: 礼花 | C12: 7 | D12: 0 | E12: 1 | F12: 170011 | G12: 170012 | H12: 礼花
A13: =(10+C13)*100&E13 -> 18001 | B13: 耳环 | C13: 8 | D13: 0 | E13: 1 | F13: 180011 | G13: 180012 | H13: 耳环
A14: =(10+C14)*100&E14 -> 19001 | B14: 项链 | C14: 9 | D14: 0 | E14: 1 | F14: 190011 | G14: 190012 | H14: 项链
A15: =(10+C15)*100&E15 -> 20001 | B15: 戒指 | C15: 10 | D15: 0 | E15: 1 | F15: 200011 | G15: 200012 | H15: 戒指

Sheet Equip
A1: ID | B1: (nouse)装备名 | C1: (nouse)装备type | D1: (nouse)具体号 | E1: 名称 | F1: 传奇装备(废弃) | G1: 外形 | H1: 种类 | I1: 基础属性id | J1: 装备专属词条 | K1: 备注
A2: id.p | B2: desc999 | C2: desc998 | D2: desc997 | E2: name | F2: legendEquip | G2: contourId | H2: type | I2: basicAttrPoolId | J2: baseModifier | K2: desc996
A3: number | B3: string | C3: string | D3: string | E3: string | F3: object | G3: number2 | H3: number | I3: number | J3: number | K3: string
A4: =H4*100+D4 -> 1100101 | B4: 火焰法杖 | C4: 法杖 | D4: 1 | E4: =B4 -> 火焰法杖 | G4: 108 | H4: =_xlfn.XLOOKUP(C4,EquipType!B:B,EquipType!A:A) -> 11001 | I4: =A4 -> 1100101 | J4: =A4 -> 1100101
A5: =H5*100+D5 -> 1100102 | B5: 冰霜法杖 | C5: 法杖 | D5: 2 | E5: =B5 -> 冰霜法杖 | G5: 109 | H5: =_xlfn.XLOOKUP(C5,EquipType!B:B,EquipType!A:A) -> 11001 | I5: =I4 -> 1100101 | J5: =A5 -> 1100102
A6: =H6*100+D6 -> 1100103 | B6: 闪电法杖 | C6: 法杖 | D6: 3 | E6: =B6 -> 闪电法杖 | G6: 105 | H6: =_xlfn.XLOOKUP(C6,EquipType!B:B,EquipType!A:A) -> 11001 | I6: =I5 -> 1100101 | J6: =A6 -> 1100103
A7: =H7*100+D7 -> 1100201 | B7: 物理长剑 | C7: 长剑 | D7: 1 | E7: =B7 -> 物理长剑 | G7: 102 | H7: =_xlfn.XLOOKUP(C7,EquipType!B:B,EquipType!A:A) -> 11002 | I7: =I6 -> 1100101 | J7: =A7 -> 1100201
A8: =H8*100+D8 -> 1100202 | B8: 冰霜长剑 | C8: 长剑 | D8: 2 | E8: =B8 -> 冰霜长剑 | G8: 106 | H8: =_xlfn.XLOOKUP(C8,EquipType!B:B,EquipType!A:A) -> 11002 | I8: =I7 -> 1100101 | J8: =A8 -> 1100202
A9: =H9*100+D9 -> 1100203 | B9: 闪电长剑 | C9: 长剑 | D9: 3 | E9: =B9 -> 闪电长剑 | G9: 105 | H9: =_xlfn.XLOOKUP(C9,EquipType!B:B,EquipType!A:A) -> 11002 | I9: =I8 -> 1100101 | J9: =A9 -> 1100203
A10: =H10*100+D10 -> 1100301 | B10: 混沌魔典 | C10: 魔典 | D10: 1 | E10: =B10 -> 混沌魔典 | G10: 105 | H10: =_xlfn.XLOOKUP(C10,EquipType!B:B,EquipType!A:A) -> 11003 | I10: =I9 -> 1100101 | J10: =A10 -> 1100301
A11: =H11*100+D11 -> 1100302 | B11: 火焰魔典 | C11: 魔典 | D11: 2 | E11: =B11 -> 火焰魔典 | G11: 108 | H11: =_xlfn.XLOOKUP(C11,EquipType!B:B,EquipType!A:A) -> 11003 | I11: =I10 -> 1100101 | J11: =A11 -> 1100302
A12: =H12*100+D12 -> 1100303 | B12: 冰霜魔典 | C12: 魔典 | D12: 3 | E12: =B12 -> 冰霜魔典 | G12: 107 | H12: =_xlfn.XLOOKUP(C12,EquipType!B:B,EquipType!A:A) -> 11003 | I12: =I11 -> 1100101 | J12: =A12 -> 1100303
A13: =H13*100+D13 -> 1200101 | B13: 铸铁头盔 | C13: 头盔 | D13: 1 | E13: =B13 -> 铸铁头盔 | F13: [[1,1]] | H13: =_xlfn.XLOOKUP(C13,EquipType!B:B,EquipType!A:A) -> 12001 | I13: =A13 -> 1200101 | J13: =A13 -> 1200101 | K13: 火gain
A14: =H14*100+D14 -> 1200102 | B14: 银制头盔 | C14: 头盔 | D14: 2 | E14: =B14 -> 银制头盔 | F14: [[1,1]] | H14: =_xlfn.XLOOKUP(C14,EquipType!B:B,EquipType!A:A) -> 12001 | I14: =I13 -> 1200101 | J14: =A14 -> 1200102 | K14: 冰gain
A15: =H15*100+D15 -> 1200103 | B15: 闪电头盔 | C15: 头盔 | D15: 3 | E15: =B15 -> 闪电头盔 | F15: [[1,1]] | H15: =_xlfn.XLOOKUP(C15,EquipType!B:B,EquipType!A:A) -> 12001 | I15: =I14 -> 1200101 | J15: =A15 -> 1200103 | K15: 电gain
A16: =H16*100+D16 -> 1300101 | B16: 铸铁胸甲 | C16: 胸甲 | D16: 1 | E16: =B16 -> 铸铁胸甲 | F16: [[1,1]] | H16: =_xlfn.XLOOKUP(C16,EquipType!B:B,EquipType!A:A) -> 13001 | I16: =A16 -> 1300101 | J16: =A16 -> 1300101 | K16: 物理gain
A17: =H17*100+D17 -> 1300102 | B17: 皮制胸甲 | C17: 胸甲 | D17: 2 | E17: =B17 -> 皮制胸甲 | F17: [[1,1]] | H17: =_xlfn.XLOOKUP(C17,EquipType!B:B,EquipType!A:A) -> 13001 | I17: =I16 -> 1300101 | J17: =A17 -> 1300102 | K17: 混沌gain
A18: =H18*100+D18 -> 1300103 | B18: 铁锁胸甲 | C18: 胸甲 | D18: 3 | E18: =B18 -> 铁锁胸甲 | F18: [[1,1]] | H18: =_xlfn.XLOOKUP(C18,EquipType!B:B,EquipType!A:A) -> 13001 | I18: =I17 -> 1300101 | J18: =A18 -> 1300103 | K18: 物理抗性
A19: =H19*100+D19 -> 1400101 | B19: 铸铁腿甲 | C19: 裤子 | D19: 1 | E19: =B19 -> 铸铁腿甲 | H19: =_xlfn.XLOOKUP(C19,EquipType!B:B,EquipType!A:A) -> 14001 | I19: =A19 -> 1400101 | J19: =A19 -> 1400101 | K19: 火抗
A20: =H20*100+D20 -> 1400102 | B20: 铸铁腿甲 | C20: 裤子 | D20: 2 | E20: =B20 -> 铸铁腿甲 | H20: =_xlfn.XLOOKUP(C20,EquipType!B:B,EquipType!A:A) -> 14001 | I20: =I19 -> 1400101 | J20: =A20 -> 1400102 | K20: 冰抗
A21: =H21*100+D21 -> 1400103 | B21: 铸铁腿甲 | C21: 裤子 | D21: 3 | E21: =B21 -> 铸铁腿甲 | H21: =_xlfn.XLOOKUP(C21,EquipType!B:B,EquipType!A:A) -> 14001 | I21: =I20 -> 1400101 | J21: =A21 -> 1400103 | K21: 电抗
A22: =H22*100+D22 -> 1500101 | B22: 铸铁靴 | C22: 鞋子 | D22: 1 | E22: =B22 -> 铸铁靴 | F22: [[1,1]] | H22: =_xlfn.XLOOKUP(C22,EquipType!B:B,EquipType!A:A) -> 15001 | I22: =A22 -> 1500101 | J22: =A22 -> 1500101 | K22: 攻击爆伤
A23: =H23*100+D23 -> 1500102 | B23: 铸铁靴 | C23: 鞋子 | D23: 2 | E23: =B23 -> 铸铁靴 | F23: [[1,1]] | H23: =_xlfn.XLOOKUP(C23,EquipType!B:B,EquipType!A:A) -> 15001 | I23: =I22 -> 1500101 | J23: =A23 -> 1500102 | K23: 法术爆伤
A24: =H24*100+D24 -> 1500103 | B24: 符文靴 | C24: 鞋子 | D24: 3 | E24: =B24 -> 符文靴 | F24: [[1,1]] | H24: =_xlfn.XLOOKUP(C24,EquipType!B:B,EquipType!A:A) -> 15001 | I24: =I23 -> 1500101 | J24: =A24 -> 1500103 | K24: 混沌抗性
A25: =H25*100+D25 -> 1600101 | B25: 铸铁护手 | C25: 手套 | D25: 1 | E25: =B25 -> 铸铁护手 | F25: [[1,1]] | H25: =_xlfn.XLOOKUP(C25,EquipType!B:B,EquipType!A:A) -> 16001 | I25: =A25 -> 1600101 | J25: =A25 -> 1600101 | K25: 攻击速度
A26: =H26*100+D26 -> 1600102 | B26: 皮制护手 | C26: 手套 | D26: 2 | E26: =B26 -> 皮制护手 | F26: [[1,1]] | H26: =_xlfn.XLOOKUP(C26,EquipType!B:B,EquipType!A:A) -> 16001 | I26: =I25 -> 1600101 | J26: =A26 -> 1600102 | K26: 施法速度
A27: =H27*100+D27 -> 1600103 | B27: 轻质护手 | C27: 手套 | D27: 3 | E27: =B27 -> 轻质护手 | F27: [[1,1],[2,1]] | H27: =_xlfn.XLOOKUP(C27,EquipType!B:B,EquipType!A:A) -> 16001 | I27: =I26 -> 1600101 | J27: =A27 -> 1600103
A28: =H28*100+D28 -> 1700101 | B28: 精铁礼花 | C28: 礼花 | D28: 1 | E28: =B28 -> 精铁礼花 | H28: =_xlfn.XLOOKUP(C28,EquipType!B:B,EquipType!A:A) -> 17001 | I28: =A28 -> 1700101 | J28: =A28 -> 1700101 | K28: 物理
A29: =H29*100+D29 -> 1700102 | B29: 宝石礼花 | C29: 礼花 | D29: 2 | E29: =B29 -> 宝石礼花 | H29: =_xlfn.XLOOKUP(C29,EquipType!B:B,EquipType!A:A) -> 17001 | I29: =I28 -> 1700101 | J29: =A29 -> 1700102 | K29: 火焰
A30: =H30*100+D30 -> 1700103 | B30: 宝石礼花 | C30: 礼花 | D30: 3 | E30: =B30 -> 宝石礼花 | H30: =_xlfn.XLOOKUP(C30,EquipType!B:B,EquipType!A:A) -> 17001 | I30: =I29 -> 1700101 | J30: =A30 -> 1700103 | K30: 冰冻
A31: =H31*100+D31 -> 1700104 | B31: 宝石礼花 | C31: 礼花 | D31: 4 | E31: =B31 -> 宝石礼花 | H31: =_xlfn.XLOOKUP(C31,EquipType!B:B,EquipType!A:A) -> 17001 | I31: =I30 -> 1700101 | J31: =A31 -> 1700104 | K31: 闪电
A32: =H32*100+D32 -> 1700105 | B32: 宝石礼花 | C32: 礼花 | D32: 5 | E32: =B32 -> 宝石礼花 | H32: =_xlfn.XLOOKUP(C32,EquipType!B:B,EquipType!A:A) -> 17001 | I32: =I31 -> 1700101 | J32: =A32 -> 1700105 | K32: 混沌
A33: =H33*100+D33 -> 1700106 | B33: 华丽礼花 | C33: 礼花 | D33: 6 | E33: =B33 -> 华丽礼花 | H33: =_xlfn.XLOOKUP(C33,EquipType!B:B,EquipType!A:A) -> 17001 | I33: =I32 -> 1700101 | J33: =A33 -> 1700106 | K33: 全伤
A34: =H34*100+D34 -> 1800101 | B34: 精铁耳环 | C34: 耳环 | D34: 1 | E34: =B34 -> 精铁耳环 | H34: =_xlfn.XLOOKUP(C34,EquipType!B:B,EquipType!A:A) -> 18001 | I34: =A34 -> 1800101 | J34: =A34 -> 1800101 | K34: 点燃
A35: =H35*100+D35 -> 1800102 | B35: 宝石耳环 | C35: 耳环 | D35: 2 | E35: =B35 -> 宝石耳环 | H35: =_xlfn.XLOOKUP(C35,EquipType!B:B,EquipType!A:A) -> 18001 | I35: =I34 -> 1800101 | J35: =A35 -> 1800102 | K35: 冰冻
A36: =H36*100+D36 -> 1800103 | B36: 宝石耳环 | C36: 耳环 | D36: 3 | E36: =B36 -> 宝石耳环 | H36: =_xlfn.XLOOKUP(C36,EquipType!B:B,EquipType!A:A) -> 18001 | I36: =I35 -> 1800101 | J36: =A36 -> 1800103 | K36: 感电
A37: =H37*100+D37 -> 1800104 | B37: 宝石耳环 | C37: 耳环 | D37: 4 | E37: =B37 -> 宝石耳环 | H37: =_xlfn.XLOOKUP(C37,EquipType!B:B,EquipType!A:A) -> 18001 | I37: =I36 -> 1800101 | J37: =A37 -> 1800104 | K37: 中毒
A38: =H38*100+D38 -> 1900101 | B38: 精铁项链 | C38: 项链 | D38: 1 | E38: =B38 -> 精铁项链 | H38: =_xlfn.XLOOKUP(C38,EquipType!B:B,EquipType!A:A) -> 19001 | I38: =A38 -> 1900101 | J38: =A38 -> 1900101 | K38: 范围
A39: =H39*100+D39 -> 1900102 | B39: 宝石项链 | C39: 项链 | D39: 2 | E39: =B39 -> 宝石项链 | H39: =_xlfn.XLOOKUP(C39,EquipType!B:B,EquipType!A:A) -> 19001 | I39: =I38 -> 1900101 | J39: =A39 -> 1900102 | K39: 近战
A40: =H40*100+D40 -> 1900103 | B40: 宝石项链 | C40: 项链 | D40: 3 | E40: =B40 -> 宝石项链 | H40: =_xlfn.XLOOKUP(C40,EquipType!B:B,EquipType!A:A) -> 19001 | I40: =I39 -> 1900101 | J40: =A40 -> 1900103 | K40: 投射
...

Sheet LegendEquip
A1: ID | B1: 传奇编号 | C1: 品质 | D1: 传奇名 | E1: (nouse)装备名 | F1: (nouse)装备type | G1: 图标 | H1: 特殊尺寸图标 | I1: 外形 | J1: 前缀词条 | K1: 后缀词条 | L1: 种类
A2: id.p | B2: legend.p | C2: quality | D2: name | E2: desc999 | F2: desc998 | G2: icon | H2: spIcon | I2: contourId | J2: modifier1 | K2: modifier2 | L2: type
A3: number | B3: number | C3: number | D3: string | E3: string | F3: string | G3: stringArr | H3: stringArr | I3: number2 | J3: numberArr | K3: numberArr | L3: number
A4: =_xlfn.XLOOKUP(E4,Equip!B:B,Equip!A:A,,0) -> 1100103 | B4: 1 | C4: 7 | D4: 风暴之眼 | E4: 闪电法杖 | F4: =_xlfn.XLOOKUP(E4,Equip!B:B,Equip!C:C,,0) -> 法杖 | G4: zhuangbei/110/109 | H4: =G4&"_big" -> zhuangbei/110/109_big | I4: 110 | J4: 90097|90098|90099 | K4: 90100|90101|90102 | L4: =_xlfn.XLOOKUP(E4,Equip!E:E,Equip!H:H) -> 11001
A5: =_xlfn.XLOOKUP(E5,Equip!B:B,Equip!A:A,,0) -> 1100201 | B5: 1 | C5: 6 | D5: 鬼乡村正 | E5: 物理长剑 | F5: =_xlfn.XLOOKUP(E5,Equip!B:B,Equip!C:C,,0) -> 长剑 | G5: zhuangbei/104/106 | H5: =G5&"_big" -> zhuangbei/104/106_big | I5: 104 | J5: 90001|90002|90003 | K5: 90004|90005|90006 | L5: =_xlfn.XLOOKUP(E5,Equip!E:E,Equip!H:H) -> 11002
A6: =_xlfn.XLOOKUP(E6,Equip!B:B,Equip!A:A,,0) -> 1100202 | B6: 1 | C6: 6 | D6: 霜之哀伤 | E6: 冰霜长剑 | F6: =_xlfn.XLOOKUP(E6,Equip!B:B,Equip!C:C,,0) -> 长剑 | G6: zhuangbei/131/106 | H6: =G6&"_big" -> zhuangbei/131/106_big | I6: 106 | J6: 90055|90056|90057 | K6: 90058|90059|90060 | L6: =_xlfn.XLOOKUP(E6,Equip!E:E,Equip!H:H) -> 11002
A7: =_xlfn.XLOOKUP(E7,Equip!B:B,Equip!A:A,,0) -> 1200101 | B7: 1 | C7: 7 | D7: 圣焰 | E7: 铸铁头盔 | F7: =_xlfn.XLOOKUP(E7,Equip!B:B,Equip!C:C,,0) -> 头盔 | G7: zhuangbei/118/202 | J7: 90145|90146|90147 | K7: 90148|90149 | L7: =_xlfn.XLOOKUP(E7,Equip!E:E,Equip!H:H) -> 12001
A8: =_xlfn.XLOOKUP(E8,Equip!B:B,Equip!A:A,,0) -> 1200102 | B8: 1 | C8: 6 | D8: 死骑之盔 | E8: 银制头盔 | F8: =_xlfn.XLOOKUP(E8,Equip!B:B,Equip!C:C,,0) -> 头盔 | G8: zhuangbei/130/202 | J8: 90037|90038 | K8: 90040|90041|90042 | L8: =_xlfn.XLOOKUP(E8,Equip!E:E,Equip!H:H) -> 12001
A9: =_xlfn.XLOOKUP(E9,Equip!B:B,Equip!A:A,,0) -> 1200103 | B9: 1 | C9: 6 | D9: 龙怒之眼 | E9: 闪电头盔 | F9: =_xlfn.XLOOKUP(E9,Equip!B:B,Equip!C:C,,0) -> 头盔 | G9: zhuangbei/118/202 | J9: 90061|90062 | K9: 90064|90065|90066 | L9: =_xlfn.XLOOKUP(E9,Equip!E:E,Equip!H:H) -> 12001
A10: =_xlfn.XLOOKUP(E10,Equip!B:B,Equip!A:A,,0) -> 1300101 | B10: 1 | C10: 6 | D10: 元素衣 | E10: 铸铁胸甲 | F10: =_xlfn.XLOOKUP(E10,Equip!B:B,Equip!C:C,,0) -> 胸甲 | G10: zhuangbei/132/304 | J10: 90013|90014 | K10: 90016|90017|90018 | L10: =_xlfn.XLOOKUP(E10,Equip!E:E,Equip!H:H) -> 13001
A11: =_xlfn.XLOOKUP(E11,Equip!B:B,Equip!A:A,,0) -> 1300102 | B11: 1 | C11: 7 | D11: 腐化侵蚀 | E11: 皮制胸甲 | F11: =_xlfn.XLOOKUP(E11,Equip!B:B,Equip!C:C,,0) -> 胸甲 | G11: zhuangbei/117/302 | J11: 90073|90074 | K11: 90076|90077 | L11: =_xlfn.XLOOKUP(E11,Equip!E:E,Equip!H:H) -> 13001
A12: =_xlfn.XLOOKUP(E12,Equip!B:B,Equip!A:A,,0) -> 1300103 | B12: 1 | C12: 7 | D12: 大法袍 | E12: 铁锁胸甲 | F12: =_xlfn.XLOOKUP(E12,Equip!B:B,Equip!C:C,,0) -> 胸甲 | G12: zhuangbei/132/304 | J12: 90103|90104 | K12: 90106|90107|90108 | L12: =_xlfn.XLOOKUP(E12,Equip!E:E,Equip!H:H) -> 13001
A13: =_xlfn.XLOOKUP(E13,Equip!B:B,Equip!A:A,,0) -> 1500103 | B13: 1 | C13: 6 | D13: 追风 | E13: 符文靴 | F13: =_xlfn.XLOOKUP(E13,Equip!B:B,Equip!C:C,,0) -> 鞋子 | G13: zhuangbei/120/401 | J13: 90019|90020 | K13: 90022|90023 | L13: =_xlfn.XLOOKUP(E13,Equip!E:E,Equip!H:H) -> 15001
A14: =_xlfn.XLOOKUP(E14,Equip!B:B,Equip!A:A,,0) -> 1500103 | B14: 2 | C14: 6 | D14: 烈火行军 | E14: 符文靴 | F14: =_xlfn.XLOOKUP(E14,Equip!B:B,Equip!C:C,,0) -> 鞋子 | G14: zhuangbei/118/401 | J14: 90109|90110 | K14: 900112|90113 | L14: =_xlfn.XLOOKUP(E14,Equip!E:E,Equip!H:H) -> 15001
A15: =_xlfn.XLOOKUP(E15,Equip!B:B,Equip!A:A,,0) -> 1500103 | B15: 3 | C15: 6 | D15: 苦行便鞋 | E15: 符文靴 | F15: =_xlfn.XLOOKUP(E15,Equip!B:B,Equip!C:C,,0) -> 鞋子 | G15: zhuangbei/133/403 | J15: 90115|90116 | K15: 90118|90119 | L15: =_xlfn.XLOOKUP(E15,Equip!E:E,Equip!H:H) -> 15001
A16: =_xlfn.XLOOKUP(E16,Equip!B:B,Equip!A:A,,0) -> 1600101 | B16: 1 | C16: 6 | D16: 轰天雷 | E16: 铸铁护手 | F16: =_xlfn.XLOOKUP(E16,Equip!B:B,Equip!C:C,,0) -> 手套 | G16: zhuangbei/121/501 | J16: 90025|90026 | K16: 90028|90029|90030 | L16: =_xlfn.XLOOKUP(E16,Equip!E:E,Equip!H:H) -> 16001
A17: =_xlfn.XLOOKUP(E17,Equip!B:B,Equip!A:A,,0) -> 1600101 | B17: 2 | C17: 6 | D17: 元素之握 | E17: 铸铁护手 | F17: =_xlfn.XLOOKUP(E17,Equip!B:B,Equip!C:C,,0) -> 手套 | G17: zhuangbei/133/504 | J17: 90031|90032 | K17: 90034|90035|90036 | L17: =_xlfn.XLOOKUP(E17,Equip!E:E,Equip!H:H) -> 16001
A18: =_xlfn.XLOOKUP(E18,Equip!B:B,Equip!A:A,,0) -> 1600101 | B18: 3 | C18: 6 | D18: 刺骨之握 | E18: 铸铁护手 | F18: =_xlfn.XLOOKUP(E18,Equip!B:B,Equip!C:C,,0) -> 手套 | G18: zhuangbei/129/504 | J18: 90043|90044 | K18: 90046|90047|90048 | L18: =_xlfn.XLOOKUP(E18,Equip!E:E,Equip!H:H) -> 16001
... A22: =_xlfn.XLOOKUP(E22,Equip!B:B,Equip!A:A,,0) -> 1700106 | B22: 1 | C22: 8 | D22: 神意 | E22: 华丽礼花 | F22: =_xlfn.XLOOKUP(E22,Equip!B:B,Equip!C:C,,0) -> 礼花 | G22: zhuangbei/110/601 | J22: 90139|90140|90141 | K22: 90142|90143 | L22: =_xlfn.XLOOKUP(E22,Equip!E:E,Equip!H:H) -> 17001
A23: =_xlfn.XLOOKUP(E23,Equip!B:B,Equip!A:A,,0) -> 1900101 | B23: 1 | C23: 6 | D23: 旋流之心 | E23: 精铁项链 | F23: =_xlfn.XLOOKUP(E23,Equip!B:B,Equip!C:C,,0) -> 项链 | G23: zhuangbei/121/801 | J23: 90007|90008 | K23: 90010 | L23: =_xlfn.XLOOKUP(E23,Equip!E:E,Equip!H:H) -> 19001
A24: =_xlfn.XLOOKUP(E24,Equip!B:B,Equip!A:A,,0) -> 1900101 | B24: 2 | C24: 7 | D24: 分形 | E24: 精铁项链 | F24: =_xlfn.XLOOKUP(E24,Equip!B:B,Equip!C:C,,0) -> 项链 | G24: zhuangbei/129/801 | J24: 90091|90092|90093 | K24: 90094|90095 | L24: =_xlfn.XLOOKUP(E24,Equip!E:E,Equip!H:H) -> 19001
A25: =_xlfn.XLOOKUP(E25,Equip!B:B,Equip!A:A,,0) -> 1900101 | B25: 3 | C25: 7 | D25: 闪电纹章 | E25: 精铁项链 | F25: =_xlfn.XLOOKUP(E25,Equip!B:B,Equip!C:C,,0) -> 项链 | G25: zhuangbei/124/801 | J25: 90121|90122 | K25: 90124|90125|90126 | L25: =_xlfn.XLOOKUP(E25,Equip!E:E,Equip!H:H) -> 19001
A26: =_xlfn.XLOOKUP(E26,Equip!B:B,Equip!A:A,,0) -> 1900102 | B26: 1 | C26: 6 | D26: 无悔决心 | E26: 宝石项链 | F26: =_xlfn.XLOOKUP(E26,Equip!B:B,Equip!C:C,,0) -> 项链 | G26: zhuangbei/130/801 | J26: 90049|90050 | K26: 90052|90053|90054 | L26: =_xlfn.XLOOKUP(E26,Equip!E:E,Equip!H:H) -> 19001
A27: =_xlfn.XLOOKUP(E27,Equip!B:B,Equip!A:A,,0) -> 2000101 | B27: 1 | C27: 6 | D27: 碎魔晶 | E27: 精铁戒指 | F27: =_xlfn.XLOOKUP(E27,Equip!B:B,Equip!C:C,,0) -> 戒指 | G27: zhuangbei/121/901 | J27: 90127|90128 | K27: 90130|90131 | L27: =_xlfn.XLOOKUP(E27,Equip!E:E,Equip!H:H) -> 20001
A28: =_xlfn.XLOOKUP(E28,Equip!B:B,Equip!A:A,,0) -> 2000102 | B28: 1 | C28: 6 | D28: 冰亡 | E28: 护法戒指 | F28: =_xlfn.XLOOKUP(E28,Equip!B:B,Equip!C:C,,0) -> 戒指 | G28: zhuangbei/131/901 | J28: 90133|90134 | K28: 90136|90137|90138 | L28: =_xlfn.XLOOKUP(E28,Equip!E:E,Equip!H:H) -> 20001

Sheet EquipQuality
A1: 装备品质 | B1: (nouse)品质 | C1: 词条评级区间 | D1: 掉落时词条数量区间 | E1: 最少词缀数量 | F1: 前缀数量上限 | G1: 后缀数量上限 | H1: 专属词条是否生效 | I1: 回收获得道具
A2: quality.p | B2: desc999 | C2: modifierTier | D2: modifierDrop | E2: modifierMin | F2: modifier1Max | G2: modifier2Max | H2: baseModifierEnable | I2: recycleItems
A3: number | B3: string | C3: numberArr | D3: numberArr | E3: number2 | F3: number | G3: number | H3: number2 | I3: object
A4: 1 | B4: 白色 | C4: 7|8 | D4: 1|1 | E4: 1 | F4: 1 | G4: 1 | H4: 0 | I4: [[2009,1]]
A5: 3 | B5: 蓝色 | C5: 4|8 | D5: 2|3 | E5: 2 | F5: 2 | G5: 2 | H5: 1 | I5: [[2009,2]]
A6: 5 | B6: 金色 | C6: 1|8 | D6: 3|4 | E6: 3 | F6: 3 | G6: 3 | H6: 1 | I6: [[2009,5]]
A7: 6 | B7: 橙色 | C7: 1|10 | D7: 6|6 | E7: 6 | F7: 3 | G7: 3 | H7: 1 | I7: [[103,1]]
A8: 7 | B8: 粉色 | C8: 1|10 | D8: 6|6 | E8: 6 | F8: 3 | G8: 3 | H8: 1 | I8: [[103,1]]
A9: 8 | B9: 红色 | C9: 1|10 | D9: 6|6 | E9: 6 | F9: 3 | G9: 3 | H9: 1 | I9: [[103,1]]

Sheet Attr
A1: ID | B1: 装等 | C1: 穿戴等级 | D1: (nouse)策划说明 | E1: 属性类型ID | F1: 属性下限（nouse） | G1: 属性上限（nouse） | H1: 属性均值（nouse） | I1: 值区间 | J1: 保留小数点
A2: id.p | B2: level.p | C2: wearLevel | D2: desc998 | E2: attrId | F2: min | G2: max | H2: avg | I2: Value | J2: round
A3: number | B3: number | C3: number | D3: string | E3: number | F3: number | G3: number | H3: number | I3: numberArr | J3: number
A4: 1100101 | B4: 1 | C4: 1 | D4: 法杖a | E4: 10000 | F4: 9 | G4: 9 | H4: 1 | I4: =_xlfn.TEXTJOIN("|",0,F4:G4) -> 9|9 | J4: 0
A5: 1100101 | B5: 4 | C5: 1 | D5: 法杖a | E5: 10000 | F5: 15 | G5: 15 | H5: 1 | I5: =_xlfn.TEXTJOIN("|",0,F5:G5) -> 15|15 | J5: 0
A6: 1100101 | B6: 8 | C6: 4 | D6: 法杖a | E6: 10000 | F6: 21 | G6: 21 | H6: 1 | I6: =_xlfn.TEXTJOIN("|",0,F6:G6) -> 21|21 | J6: 0
A7: 1100101 | B7: 13 | C7: 8 | D7: 法杖a | E7: 10000 | F7: 27 | G7: 27 | H7: 1 | I7: =_xlfn.TEXTJOIN("|",0,F7:G7) -> 27|27 | J7: 0
A8: 1100101 | B8: 19 | C8: 13 | D8: 法杖a | E8: 10000 | F8: 36 | G8: 36 | H8: 1 | I8: =_xlfn.TEXTJOIN("|",0,F8:G8) -> 36|36 | J8: 0
A9: 1100101 | B9: 25 | C9: 19 | D9: 法杖a | E9: 10000 | F9: 54 | G9: 54 | H9: 1 | I9: =_xlfn.TEXTJOIN("|",0,F9:G9) -> 54|54 | J9: 0
A10: 1100101 | B10: 31 | C10: 25 | D10: 法杖a | E10: 10000 | F10: 72 | G10: 72 | H10: 1 | I10: =_xlfn.TEXTJOIN("|",0,F10:G10) -> 72|72 | J10: 0
A11: 1100101 | B11: 37 | C11: 31 | D11: 法杖a | E11: 10000 | F11: 108 | G11: 108 | H11: 1 | I11: =_xlfn.TEXTJOIN("|",0,F11:G11) -> 108|108 | J11: 0
A12: 1100101 | B12: 43 | C12: 37 | D12: 法杖a | E12: 10000 | F12: 144 | G12: 144 | H12: 1 | I12: =_xlfn.TEXTJOIN("|",0,F12:G12) -> 144|144 | J12: 0
A13: 1100101 | B13: 49 | C13: 43 | D13: 法杖a | E13: 10000 | F13: 288 | G13: 288 | H13: 1 | I13: =_xlfn.TEXTJOIN("|",0,F13:G13) -> 288|288 | J13: 0
A14: 1100101 | B14: 55 | C14: 49 | D14: 法杖a | E14: 10000 | F14: 576 | G14: 576 | H14: 1 | I14: =_xlfn.TEXTJOIN("|",0,F14:G14) -> 576|576 | J14: 0
A15: 1100101 | B15: 61 | C15: 55 | D15: 法杖a | E15: 10000 | F15: 1152 | G15: 1152 | H15: 1 | I15: =_xlfn.TEXTJOIN("|",0,F15:G15) -> 1152|1152 | J15: 0
... A198: 2200101 | B198: 90 | C198: 75 | D198: 羽饰a | E198: 10313 | F198: 0.15 | G198: 0.2 | H198: 1 | I198: =_xlfn.TEXTJOIN("|",0,F198:G198) -> 0.15|0.2 | J198: 2

Sheet ModifierPool
A1: id | B1: 备注(nouse) | C1: 是否按顺序取出(传奇装备用) | D1: 词条池
A2: id.p | B2: desc999 | C2: ifOrder | D2: modifier
A3: number | B3: string | C3: number2 | D3: numberArr
A4: 110011 | B4: 法杖前缀 | D4: 1201|1202|1203|1204|1205|1206|1207|1208|1209|1210|1211|1212|1213
A5: 110012 | B5: 法杖后缀 | D5: 1251|1252|1253|1254|1255|1256|1257|1258|1259|1260|1261|1262|1263|1264|1265|1266|1267|1268|1269|1270|1271|1272|1273
A6: 110021 | B6: 长剑前缀 | D6: 1|2|3|4|5|6|7|8|9|10|11|12|13
A7: 110022 | B7: 长剑后缀 | D7: 51|52|53|54|55|56|57|59|60|61|62|63|64|65|66|67|68|69|70|71|72|73|74
A8: 120011 | B8: 头盔前缀 | D8: 101|102|103|104|105|106|107|108|109|110|111|112|113|114
A9: 120012 | B9: 头盔后缀 | D9: 151|152|153|154|155|156|157|158|159|160|161|162|163|164
A10: 130011 | B10: 胸甲前缀 | D10: 201|202|203|204|205|206|207|208|209|210|211|212|213|214
A11: 130012 | B11: 胸甲后缀 | D11: 251|252|253|254|255|256|257|258|259|260|261|262|263|264
A12: 140011 | B12: 裤子前缀 | D12: 301|302|303|304|305|306|307|308|309|310|311|312|313|314
A13: 140012 | B13: 裤子后缀 | D13: 351|352|353|354|355|356|357|358|359|360|361|362|363|364
A14: 150011 | B14: 鞋子前缀 | D14: 401|402|403|404|405|406|407|408|409|410|411|412|413|414
A15: 150012 | B15: 鞋子后缀 | D15: 451|452|453|454|455|456|457|458|459|460|461|462|463|464
... A29: 220012 | B29: 羽饰后缀 | D29: 1151|1152|1153|1154|1155|1156|1157|1158|1159|1160|1161|1162|1163|1164

Sheet Modifier
A1: id | B1: 评级 | C1: 备注(nouse) | D1: (nouse)所属type | E1: (nouse)所属词位 | F1: 名称 | G1: 词缀前后 | H1: 权重 | I1: 互斥组 | J1: 解锁装等 | K1: 描述 | L1: 词缀类型 | M1: 特技 | N1: 效果 | O1: 提供属性 | P1: 随机值属性名 | Q1: 随机下限 | R1: 随机上限 | S1: 保留小数位 | T1: 显示类型
A2: id.p | B2: tier.p | C2: desc999 | D2: desc998 | E2: desc997 | F2: name | G2: modifierPosition | H2: weigh | I2: repel | J2: level | K2: desc | L2: modifierType | M2: stunt | N2: affix | O2: attr | P2: randomValue | Q2: min | R2: max | S2: round | T2: showType
A3: number | B3: number | C3: string | D3: string | E3: string | F3: string | G3: number2 | H3: number2 | I3: number2 | J3: number2 | K3: string | L3: number2 | M3: numberArr | N3: number2 | O3: number2 | P3: string | Q3: number2 | R3: number2 | S3: number2 | T3: number2
A4: 1 | B4: 1 | C4: 物理伤害倍率增加 | D4: 长剑 | E4: 前缀 | G4: 1 | H4: 50 | J4: {=_xlfn.SWITCH(B4,1,75,2,61,3,49,4,37,5,25,6,13,7,4,8,1)} -> 75 | K4: {=IFERROR(_xlfn.SWITCH(L4,2,_xlfn.XLOOKUP(C4,[1]ModifierDes!$B:$B,[1]ModifierDes!$C:$C),3,_xlfn.XLOOKUP(C4,[1]StuntDes!$B:$B,[1]StuntDes!$C:$C)),"")} -> 物理伤害倍率增加{0} | L4: =IF(M4="",IF(N4="",1,2),3) -> 2 | M4: =IFERROR(_xlfn.XLOOKUP(C4,[1]StuntDes!$B:$B,[1]StuntDes!$A:$A),"") | N4: =IFERROR(_xlfn.XLOOKUP(C4,[1]ModifierDes!$B:$B,[1]ModifierDes!$A:$A),"") -> 10056 | O4: =IFERROR(_xlfn.XLOOKUP(C4,[1]AttributeName!$C:$C,[1]AttributeName!$B:$B),"") | Q4: 0.5 | R4: 0.7 | S4: {=IFERROR(_xlfn.SWITCH(L4,1,_xlfn.XLOOKUP(O4,[1]AttributeName!$B:$B,[1]AttributeName!$D:$D),2,_xlfn.XLOOKUP(C4,#REF!,#REF!),3,_xlfn.XLOOKUP(C4,#REF!,#REF!)),0)} -> 0 | T4: {=IFERROR(_xlfn.SWITCH(L4,1,_xlfn.XLOOKUP(O4,[1]AttributeName!$B:$B,[1]AttributeName!$E:$E),2,_xlfn.XLOOKUP(C4,#REF!,#REF!),3,_xlfn.XLOOKUP(C4,#REF!,#REF!)),0)} -> 0
A5: 1 | B5: 2 | C5: 物理伤害倍率增加 | D5: 长剑 | E5: 前缀 | G5: 1 | H5: 100 | J5: {=_xlfn.SWITCH(B5,1,75,2,61,3,49,4,37,5,25,6,13,7,4,8,1)} -> 61 | K5: {=IFERROR(_xlfn.SWITCH(L5,2,_xlfn.XLOOKUP(C5,[1]ModifierDes!$B:$B,[1]ModifierDes!$C:$C),3,_xlfn.XLOOKUP(C5,[1]StuntDes!$B:$B,[1]StuntDes!$C:$C)),"")} -> 物理伤害倍率增加{0} | L5: =IF(M5="",IF(N5="",1,2),3) -> 2 | M5: =IFERROR(_xlfn.XLOOKUP(C5,[1]StuntDes!$B:$B,[1]StuntDes!$A:$A),"") | N5: =IFERROR(_xlfn.XLOOKUP(C5,[1]ModifierDes!$B:$B,[1]ModifierDes!$A:$A),"") -> 10056 | O5: =IFERROR(_xlfn.XLOOKUP(C5,[1]AttributeName!$C:$C,[1]AttributeName!$B:$B),"") | Q5: 0.44 | R5: 0.49 | S5: {=IFERROR(_xlfn.SWITCH(L5,1,_xlfn.XLOOKUP(O5,[1]AttributeName!$B:$B,[1]AttributeName!$D:$D),2,_xlfn.XLOOKUP(C5,#REF!,#REF!),3,_xlfn.XLOOKUP(C5,#REF!,#REF!)),0)} -> 0 | T5: {=IFERROR(_xlfn.SWITCH(L5,1,_xlfn.XLOOKUP(O5,[1]AttributeName!$B:$B,[1]AttributeName!$E:$E),2,_xlfn.XLOOKUP(C5,#REF!,#REF!),3,_xlfn.XLOOKUP(C5,#REF!,#REF!)),0)} -> 0
A6: 1 | B6: 3 | C6: 物理伤害倍率增加 | D6: 长剑 | E6: 前缀 | G6: 1 | H6: 200 | J6: {=_xlfn.SWITCH(B6,1,75,2,61,3,49,4,37,5,25,6,13,7,4,8,1)} -> 49 | K6: {=IFERROR(_xlfn.SWITCH(L6,2,_xlfn.XLOOKUP(C6,[1]ModifierDes!$B:$B,[1]ModifierDes!$C:$C),3,_xlfn.XLOOKUP(C6,[1]StuntDes!$B:$B,[1]StuntDes!$C:$C)),"")} -> 物理伤害倍率增加{0} | L6: =IF(M6="",IF(N6="",1,2),3) -> 2 | M6: =IFERROR(_xlfn.XLOOKUP(C6,[1]StuntDes!$B:$B,[1]StuntDes!$A:$A),"") | N6: =IFERROR(_xlfn.XLOOKUP(C6,[1]ModifierDes!$B:$B,[1]ModifierDes!$A:$A),"") -> 10056 | O6: =IFERROR(_xlfn.XLOOKUP(C6,[1]AttributeName!$C:$C,[1]AttributeName!$B:$B),"") | Q6: 0.38 | R6: 0.43 | S6: {=IFERROR(_xlfn.SWITCH(L6,1,_xlfn.XLOOKUP(O6,[1]AttributeName!$B:$B,[1]AttributeName!$D:$D),2,_xlfn.XLOOKUP(C6,#REF!,#REF!),3,_xlfn.XLOOKUP(C6,#REF!,#REF!)),0)} -> 0 | T6: {=IFERROR(_xlfn.SWITCH(L6,1,_xlfn.XLOOKUP(O6,[1]AttributeName!$B:$B,[1]AttributeName!$E:$E),2,_xlfn.XLOOKUP(C6,#REF!,#REF!),3,_xlfn.XLOOKUP(C6,#REF!,#REF!)),0)} -> 0
A7: 1 | B7: 4 | C7: 物理伤害倍率增加 | D7: 长剑 | E7: 前缀 | G7: 1 | H7: 500 | J7: {=_xlfn.SWITCH(B7,1,75,2,61,3,49,4,37,5,25,6,13,7,4,8,1)} -> 37 | K7: {=IFERROR(_xlfn.SWITCH(L7,2,_xlfn.XLOOKUP(C7,[1]ModifierDes!$B:$B,[1]ModifierDes!$C:$C),3,_xlfn.XLOOKUP(C7,[1]StuntDes!$B:$B,[1]StuntDes!$C:$C)),"")} -> 物理伤害倍率增加{0} | L7: =IF(M7="",IF(N7="",1,2),3) -> 2 | M7: =IFERROR(_xlfn.XLOOKUP(C7,[1]StuntDes!$B:$B,[1]StuntDes!$A:$A),"") | N7: =IFERROR(_xlfn.XLOOKUP(C7,[1]ModifierDes!$B:$B,[1]ModifierDes!$A:$A),"") -> 10056 | O7: =IFERROR(_xlfn.XLOOKUP(C7,[1]AttributeName!$C:$C,[1]AttributeName!$B:$B),"") | Q7: 0.32 | R7: 0.37 | S7: {=IFERROR(_xlfn.SWITCH(L7,1,_xlfn.XLOOKUP(O7,[1]AttributeName!$B:$B,[1]AttributeName!$D:$D),2,_xlfn.XLOOKUP(C7,#REF!,#REF!),3,_xlfn.XLOOKUP(C7,#REF!,#REF!)),0)} -> 0 | T7: {=IFERROR(_xlfn.SWITCH(L7,1,_xlfn.XLOOKUP(O7,[1]AttributeName!$B:$B,[1]AttributeName!$E:$E),2,_xlfn.XLOOKUP(C7,#REF!,#REF!),3,_xlfn.XLOOKUP(C7,#REF!,#REF!)),0)} -> 0
A8: 1 | B8: 5 | C8: 物理伤害倍率增加 | D8: 长剑 | E8: 前缀 | G8: 1 | H8: 1000 | J8: {=_xlfn.SWITCH(B8,1,75,2,61,3,49,4,37,5,25,6,13,7,4,8,1)} -> 25 | K8: {=IFERROR(_xlfn.SWITCH(L8,2,_xlfn.XLOOKUP(C8,[1]ModifierDes!$B:$B,[1]ModifierDes!$C:$C),3,_xlfn.XLOOKUP(C8,[1]StuntDes!$B:$B,[1]StuntDes!$C:$C)),"")} -> 物理伤害倍率增加{0} | L8: =IF(M8="",IF(N8="",1,2),3) -> 2 | M8: =IFERROR(_xlfn.XLOOKUP(C8,[1]StuntDes!$B:$B,[1]StuntDes!$A:$A),"") | N8: =IFERROR(_xlfn.XLOOKUP(C8,[1]ModifierDes!$B:$B,[1]ModifierDes!$A:$A),"") -> 10056 | O8: =IFERROR(_xlfn.XLOOKUP(C8,[1]AttributeName!$C:$C,[1]AttributeName!$B:$B),"") | Q8: 0.26 | R8: 0.31 | S8: {=IFERROR(_xlfn.SWITCH(L8,1,_xlfn.XLOOKUP(O8,[1]AttributeName!$B:$B,[1]AttributeName!$D:$D),2,_xlfn.XLOOKUP(C8,#REF!,#REF!),3,_xlfn.XLOOKUP(C8,#REF!,#REF!)),0)} -> 0 | T8: {=IFERROR(_xlfn.SWITCH(L8,1,_xlfn.XLOOKUP(O8,[1]AttributeName!$B:$B,[1]AttributeName!$E:$E),2,_xlfn.XLOOKUP(C8,#REF!,#REF!),3,_xlfn.XLOOKUP(C8,#REF!,#REF!)),0)} -> 0
A9: 1 | B9: 6 | C9: 物理伤害倍率增加 | D9: 长剑 | E9: 前缀 | G9: 1 | H9: 1000 | J9: {=_xlfn.SWITCH(B9,1,75,2,61,3,49,4,37,5,25,6,13,7,4,8,1)} -> 13 | K9: {=IFERROR(_xlfn.SWITCH(L9,2,_xlfn.XLOOKUP(C9,[1]ModifierDes!$B:$B,[1]ModifierDes!$C:$C),3,_xlfn.XLOOKUP(C9,[1]StuntDes!$B:$B,[1]StuntDes!$C:$C)),"")} -> 物理伤害倍率增加{0} | L9: =IF(M9="",IF(N9="",1,2),3) -> 2 | M9: =IFERROR(_xlfn.XLOOKUP(C9,[1]StuntDes!$B:$B,[1]StuntDes!$A:$A),"") | N9: =IFERROR(_xlfn.XLOOKUP(C9,[1]ModifierDes!$B:$B,[1]ModifierDes!$A:$A),"") -> 10056 | O9: =IFERROR(_xlfn.XLOOKUP(C9,[1]AttributeName!$C:$C,[1]AttributeName!$B:$B),"") | Q9: 0.2 | R9: 0.25 | S9: {=IFERROR(_xlfn.SWITCH(L9,1,_xlfn.XLOOKUP(O9,[1]AttributeName!$B:$B,[1]AttributeName!$D:$D),2,_xlfn.XLOOKUP(C9,#REF!,#REF!),3,_xlfn.XLOOKUP(C9,#REF!,#REF!)),0)} -> 0 | T9: {=IFERROR(_xlfn.SWITCH(L9,1,_xlfn.XLOOKUP(O9,[1]AttributeName!$B:$B,[1]AttributeName!$E:$E),2,_xlfn.XLOOKUP(C9,#REF!,#REF!),3,_xlfn.XLOOKUP(C9,#REF!,#REF!)),0)} -> 0
A10: 1 | B10: 7 | C10: 物理伤害倍率增加 | D10: 长剑 | E10: 前缀 | G10: 1 | H10: 1000 | J10: {=_xlfn.SWITCH(B10,1,75,2,61,3,49,4,37,5,25,6,13,7,4,8,1)} -> 4 | K10: {=IFERROR(_xlfn.SWITCH(L10,2,_xlfn.XLOOKUP(C10,[1]ModifierDes!$B:$B,[1]ModifierDes!$C:$C),3,_xlfn.XLOOKUP(C10,[1]StuntDes!$B:$B,[1]StuntDes!$C:$C)),"")} -> 物理伤害倍率增加{0} | L10: =IF(M10="",IF(N10="",1,2),3) -> 2 | M10: =IFERROR(_xlfn.XLOOKUP(C10,[1]StuntDes!$B:$B,[1]StuntDes!$A:$A),"") | N10: =IFERROR(_xlfn.XLOOKUP(C10,[1]ModifierDes!$B:$B,[1]ModifierDes!$A:$A),"") -> 10056 | O10: =IFERROR(_xlfn.XLOOKUP(C10,[1]AttributeName!$C:$C,[1]AttributeName!$B:$B),"") | Q10: 0.14 | R10: 0.19 | S10: {=IFERROR(_xlfn.SWITCH(L10,1,_xlfn.XLOOKUP(O10,[1]AttributeName!$B:$B,[1]AttributeName!$D:$D),2,_xlfn.XLOOKUP(C10,#REF!,#REF!),3,_xlfn.XLOOKUP(C10,#REF!,#REF!)),0)} -> 0 | T10: {=IFERROR(_xlfn.SWITCH(L10,1,_xlfn.XLOOKUP(O10,[1]AttributeName!$B:$B,[1]AttributeName!$E:$E),2,_xlfn.XLOOKUP(C10,#REF!,#REF!),3,_xlfn.XLOOKUP(C10,#REF!,#REF!)),0)} -> 0
A11: 1 | B11: 8 | C11: 物理伤害倍率增加 | D11: 长剑 | E11: 前缀 | G11: 1 | H11: 1000 | J11: {=_xlfn.SWITCH(B11,1,75,2,61,3,49,4,37,5,25,6,13,7,4,8,1)} -> 1 | K11: {=IFERROR(_xlfn.SWITCH(L11,2,_xlfn.XLOOKUP(C11,[1]ModifierDes!$B:$B,[1]ModifierDes!$C:$C),3,_xlfn.XLOOKUP(C11,[1]StuntDes!$B:$B,[1]StuntDes!$C:$C)),"")} -> 物理伤害倍率增加{0} | L11: =IF(M11="",IF(N11="",1,2),3) -> 2 | M11: =IFERROR(_xlfn.XLOOKUP(C11,[1]StuntDes!$B:$B,[1]StuntDes!$A:$A),"") | N11: =IFERROR(_xlfn.XLOOKUP(C11,[1]ModifierDes!$B:$B,[1]ModifierDes!$A:$A),"") -> 10056 | O11: =IFERROR(_xlfn.XLOOKUP(C11,[1]AttributeName!$C:$C,[1]AttributeName!$B:$B),"") | Q11: 0.08 | R11: 0.13 | S11: {=IFERROR(_xlfn.SWITCH(L11,1,_xlfn.XLOOKUP(O11,[1]AttributeName!$B:$B,[1]AttributeName!$D:$D),2,_xlfn.XLOOKUP(C11,#REF!,#REF!),3,_xlfn.XLOOKUP(C11,#REF!,#REF!)),0)} -> 0 | T11: {=IFERROR(_xlfn.SWITCH(L11,1,_xlfn.XLOOKUP(O11,[1]AttributeName!$B:$B,[1]AttributeName!$E:$E),2,_xlfn.XLOOKUP(C11,#REF!,#REF!),3,_xlfn.XLOOKUP(C11,#REF!,#REF!)),0)} -> 0
A12: =A4+1 -> 2 | B12: 1 | C12: 火焰伤害倍率增加 | D12: 长剑 | E12: 前缀 | G12: 1 | H12: 50 | J12: {=_xlfn.SWITCH(B12,1,75,2,61,3,49,4,37,5,25,6,13,7,4,8,1)} -> 75 | K12: {=IFERROR(_xlfn.SWITCH(L12,2,_xlfn.XLOOKUP(C12,[1]ModifierDes!$B:$B,[1]ModifierDes!$C:$C),3,_xlfn.XLOOKUP(C12,[1]StuntDes!$B:$B,[1]StuntDes!$C:$C)),"")} -> 火焰伤害倍率增加{0} | L12: =IF(M12="",IF(N12="",1,2),3) -> 2 | M12: =IFERROR(_xlfn.XLOOKUP(C12,[1]StuntDes!$B:$B,[1]StuntDes!$A:$A),"") | N12: =IFERROR(_xlfn.XLOOKUP(C12,[1]ModifierDes!$B:$B,[1]ModifierDes!$A:$A),"") -> 10057 | O12: =IFERROR(_xlfn.XLOOKUP(C12,[1]AttributeName!$C:$C,[1]AttributeName!$B:$B),"") | Q12: 0.5 | R12: 0.7 | S12: {=IFERROR(_xlfn.SWITCH(L12,1,_xlfn.XLOOKUP(O12,[1]AttributeName!$B:$B,[1]AttributeName!$D:$D),2,_xlfn.XLOOKUP(C12,#REF!,#REF!),3,_xlfn.XLOOKUP(C12,#REF!,#REF!)),0)} -> 0 | T12: {=IFERROR(_xlfn.SWITCH(L12,1,_xlfn.XLOOKUP(O12,[1]AttributeName!$B:$B,[1]AttributeName!$E:$E),2,_xlfn.XLOOKUP(C12,#REF!,#REF!),3,_xlfn.XLOOKUP(C12,#REF!,#REF!)),0)} -> 0
A13: =A5+1 -> 2 | B13: 2 | C13: 火焰伤害倍率增加 | D13: 长剑 | E13: 前缀 | G13: 1 | H13: 100 | J13: {=_xlfn.SWITCH(B13,1,75,2,61,3,49,4,37,5,25,6,13,7,4,8,1)} -> 61 | K13: {=IFERROR(_xlfn.SWITCH(L13,2,_xlfn.XLOOKUP(C13,[1]ModifierDes!$B:$B,[1]ModifierDes!$C:$C),3,_xlfn.XLOOKUP(C13,[1]StuntDes!$B:$B,[1]StuntDes!$C:$C)),"")} -> 火焰伤害倍率增加{0} | L13: =IF(M13="",IF(N13="",1,2),3) -> 2 | M13: =IFERROR(_xlfn.XLOOKUP(C13,[1]StuntDes!$B:$B,[1]StuntDes!$A:$A),"") | N13: =IFERROR(_xlfn.XLOOKUP(C13,[1]ModifierDes!$B:$B,[1]ModifierDes!$A:$A),"") -> 10057 | O13: =IFERROR(_xlfn.XLOOKUP(C13,[1]AttributeName!$C:$C,[1]AttributeName!$B:$B),"") | Q13: 0.44 | R13: 0.49 | S13: {=IFERROR(_xlfn.SWITCH(L13,1,_xlfn.XLOOKUP(O13,[1]AttributeName!$B:$B,[1]AttributeName!$D:$D),2,_xlfn.XLOOKUP(C13,#REF!,#REF!),3,_xlfn.XLOOKUP(C13,#REF!,#REF!)),0)} -> 0 | T13: {=IFERROR(_xlfn.SWITCH(L13,1,_xlfn.XLOOKUP(O13,[1]AttributeName!$B:$B,[1]AttributeName!$E:$E),2,_xlfn.XLOOKUP(C13,#REF!,#REF!),3,_xlfn.XLOOKUP(C13,#REF!,#REF!)),0)} -> 0
A14: =A6+1 -> 2 | B14: 3 | C14: 火焰伤害倍率增加 | D14: 长剑 | E14: 前缀 | G14: 1 | H14: 200 | J14: {=_xlfn.SWITCH(B14,1,75,2,61,3,49,4,37,5,25,6,13,7,4,8,1)} -> 49 | K14: {=IFERROR(_xlfn.SWITCH(L14,2,_xlfn.XLOOKUP(C14,[1]ModifierDes!$B:$B,[1]ModifierDes!$C:$C),3,_xlfn.XLOOKUP(C14,[1]StuntDes!$B:$B,[1]StuntDes!$C:$C)),"")} -> 火焰伤害倍率增加{0} | L14: =IF(M14="",IF(N14="",1,2),3) -> 2 | M14: =IFERROR(_xlfn.XLOOKUP(C14,[1]StuntDes!$B:$B,[1]StuntDes!$A:$A),"") | N14: =IFERROR(_xlfn.XLOOKUP(C14,[1]ModifierDes!$B:$B,[1]ModifierDes!$A:$A),"") -> 10057 | O14: =IFERROR(_xlfn.XLOOKUP(C14,[1]AttributeName!$C:$C,[1]AttributeName!$B:$B),"") | Q14: 0.38 | R14: 0.43 | S14: {=IFERROR(_xlfn.SWITCH(L14,1,_xlfn.XLOOKUP(O14,[1]AttributeName!$B:$B,[1]AttributeName!$D:$D),2,_xlfn.XLOOKUP(C14,#REF!,#REF!),3,_xlfn.XLOOKUP(C14,#REF!,#REF!)),0)} -> 0 | T14: {=IFERROR(_xlfn.SWITCH(L14,1,_xlfn.XLOOKUP(O14,[1]AttributeName!$B:$B,[1]AttributeName!$E:$E),2,_xlfn.XLOOKUP(C14,#REF!,#REF!),3,_xlfn.XLOOKUP(C14,#REF!,#REF!)),0)} -> 0
A15: =A7+1 -> 2 | B15: 4 | C15: 火焰伤害倍率增加 | D15: 长剑 | E15: 前缀 | G15: 1 | H15: 500 | J15: {=_xlfn.SWITCH(B15,1,75,2,61,3,49,4,37,5,25,6,13,7,4,8,1)} -> 37 | K15: {=IFERROR(_xlfn.SWITCH(L15,2,_xlfn.XLOOKUP(C15,[1]ModifierDes!$B:$B,[1]ModifierDes!$C:$C),3,_xlfn.XLOOKUP(C15,[1]StuntDes!$B:$B,[1]StuntDes!$C:$C)),"")} -> 火焰伤害倍率增加{0} | L15: =IF(M15="",IF(N15="",1,2),3) -> 2 | M15: =IFERROR(_xlfn.XLOOKUP(C15,[1]StuntDes!$B:$B,[1]StuntDes!$A:$A),"") | N15: =IFERROR(_xlfn.XLOOKUP(C15,[1]ModifierDes!$B:$B,[1]ModifierDes!$A:$A),"") -> 10057 | O15: =IFERROR(_xlfn.XLOOKUP(C15,[1]AttributeName!$C:$C,[1]AttributeName!$B:$B),"") | Q15: 0.32 | R15: 0.37 | S15: {=IFERROR(_xlfn.SWITCH(L15,1,_xlfn.XLOOKUP(O15,[1]AttributeName!$B:$B,[1]AttributeName!$D:$D),2,_xlfn.XLOOKUP(C15,#REF!,#REF!),3,_xlfn.XLOOKUP(C15,#REF!,#REF!)),0)} -> 0 | T15: {=IFERROR(_xlfn.SWITCH(L15,1,_xlfn.XLOOKUP(O15,[1]AttributeName!$B:$B,[1]AttributeName!$E:$E),2,_xlfn.XLOOKUP(C15,#REF!,#REF!),3,_xlfn.XLOOKUP(C15,#REF!,#REF!)),0)} -> 0
A16: =A8+1 -> 2 | B16: 5 | C16: 火焰伤害倍率增加 | D16: 长剑 | E16: 前缀 | G16: 1 | H16: 1000 | J16: {=_xlfn.SWITCH(B16,1,75,2,61,3,49,4,37,5,25,6,13,7,4,8,1)} -> 25 | K16: {=IFERROR(_xlfn.SWITCH(L16,2,_xlfn.XLOOKUP(C16,[1]ModifierDes!$B:$B,[1]ModifierDes!$C:$C),3,_xlfn.XLOOKUP(C16,[1]StuntDes!$B:$B,[1]StuntDes!$C:$C)),"")} -> 火焰伤害倍率增加{0} | L16: =IF(M16="",IF(N16="",1,2),3) -> 2 | M16: =IFERROR(_xlfn.XLOOKUP(C16,[1]StuntDes!$B:$B,[1]StuntDes!$A:$A),"") | N16: =IFERROR(_xlfn.XLOOKUP(C16,[1]ModifierDes!$B:$B,[1]ModifierDes!$A:$A),"") -> 10057 | O16: =IFERROR(_xlfn.XLOOKUP(C16,[1]AttributeName!$C:$C,[1]AttributeName!$B:$B),"") | Q16: 0.26 | R16: 0.31 | S16: {=IFERROR(_xlfn.SWITCH(L16,1,_xlfn.XLOOKUP(O16,[1]AttributeName!$B:$B,[1]AttributeName!$D:$D),2,_xlfn.XLOOKUP(C16,#REF!,#REF!),3,_xlfn.XLOOKUP(C16,#REF!,#REF!)),0)} -> 0 | T16: {=IFERROR(_xlfn.SWITCH(L16,1,_xlfn.XLOOKUP(O16,[1]AttributeName!$B:$B,[1]AttributeName!$E:$E),2,_xlfn.XLOOKUP(C16,#REF!,#REF!),3,_xlfn.XLOOKUP(C16,#REF!,#REF!)),0)} -> 0
A17: =A9+1 -> 2 | B17: 6 | C17: 火焰伤害倍率增加 | D17: 长剑 | E17: 前缀 | G17: 1 | H17: 1000 | J17: {=_xlfn.SWITCH(B17,1,75,2,61,3,49,4,37,5,25,6,13,7,4,8,1)} -> 13 | K17: {=IFERROR(_xlfn.SWITCH(L17,2,_xlfn.XLOOKUP(C17,[1]ModifierDes!$B:$B,[1]ModifierDes!$C:$C),3,_xlfn.XLOOKUP(C17,[1]StuntDes!$B:$B,[1]StuntDes!$C:$C)),"")} -> 火焰伤害倍率增加{0} | L17: =IF(M17="",IF(N17="",1,2),3) -> 2 | M17: =IFERROR(_xlfn.XLOOKUP(C17,[1]StuntDes!$B:$B,[1]StuntDes!$A:$A),"") | N17: =IFERROR(_xlfn.XLOOKUP(C17,[1]ModifierDes!$B:$B,[1]ModifierDes!$A:$A),"") -> 10057 | O17: =IFERROR(_xlfn.XLOOKUP(C17,[1]AttributeName!$C:$C,[1]AttributeName!$B:$B),"") | Q17: 0.2 | R17: 0.25 | S17: {=IFERROR(_xlfn.SWITCH(L17,1,_xlfn.XLOOKUP(O17,[1]AttributeName!$B:$B,[1]AttributeName!$D:$D),2,_xlfn.XLOOKUP(C17,#REF!,#REF!),3,_xlfn.XLOOKUP(C17,#REF!,#REF!)),0)} -> 0 | T17: {=IFERROR(_xlfn.SWITCH(L17,1,_xlfn.XLOOKUP(O17,[1]AttributeName!$B:$B,[1]AttributeName!$E:$E),2,_xlfn.XLOOKUP(C17,#REF!,#REF!),3,_xlfn.XLOOKUP(C17,#REF!,#REF!)),0)} -> 0
A18: =A10+1 -> 2 | B18: 7 | C18: 火焰伤害倍率增加 | D18: 长剑 | E18: 前缀 | G18: 1 | H18: 1000 | J18: {=_xlfn.SWITCH(B18,1,75,2,61,3,49,4,37,5,25,6,13,7,4,8,1)} -> 4 | K18: {=IFERROR(_xlfn.SWITCH(L18,2,_xlfn.XLOOKUP(C18,[1]ModifierDes!$B:$B,[1]ModifierDes!$C:$C),3,_xlfn.XLOOKUP(C18,[1]StuntDes!$B:$B,[1]StuntDes!$C:$C)),"")} -> 火焰伤害倍率增加{0} | L18: =IF(M18="",IF(N18="",1,2),3) -> 2 | M18: =IFERROR(_xlfn.XLOOKUP(C18,[1]StuntDes!$B:$B,[1]StuntDes!$A:$A),"") | N18: =IFERROR(_xlfn.XLOOKUP(C18,[1]ModifierDes!$B:$B,[1]ModifierDes!$A:$A),"") -> 10057 | O18: =IFERROR(_xlfn.XLOOKUP(C18,[1]AttributeName!$C:$C,[1]AttributeName!$B:$B),"") | Q18: 0.14 | R18: 0.19 | S18: {=IFERROR(_xlfn.SWITCH(L18,1,_xlfn.XLOOKUP(O18,[1]AttributeName!$B:$B,[1]AttributeName!$D:$D),2,_xlfn.XLOOKUP(C18,#REF!,#REF!),3,_xlfn.XLOOKUP(C18,#REF!,#REF!)),0)} -> 0 | T18: {=IFERROR(_xlfn.SWITCH(L18,1,_xlfn.XLOOKUP(O18,[1]AttributeName!$B:$B,[1]AttributeName!$E:$E),2,_xlfn.XLOOKUP(C18,#REF!,#REF!),3,_xlfn.XLOOKUP(C18,#REF!,#REF!)),0)} -> 0
A19: =A11+1 -> 2 | B19: 8 | C19: 火焰伤害倍率增加 | D19: 长剑 | E19: 前缀 | G19: 1 | H19: 1000 | J19: {=_xlfn.SWITCH(B19,1,75,2,61,3,49,4,37,5,25,6,13,7,4,8,1)} -> 1 | K19: {=IFERROR(_xlfn.SWITCH(L19,2,_xlfn.XLOOKUP(C19,[1]ModifierDes!$B:$B,[1]ModifierDes!$C:$C),3,_xlfn.XLOOKUP(C19,[1]StuntDes!$B:$B,[1]StuntDes!$C:$C)),"")} -> 火焰伤害倍率增加{0} | L19: =IF(M19="",IF(N19="",1,2),3) -> 2 | M19: =IFERROR(_xlfn.XLOOKUP(C19,[1]StuntDes!$B:$B,[1]StuntDes!$A:$A),"") | N19: =IFERROR(_xlfn.XLOOKUP(C19,[1]ModifierDes!$B:$B,[1]ModifierDes!$A:$A),"") -> 10057 | O19: =IFERROR(_xlfn.XLOOKUP(C19,[1]AttributeName!$C:$C,[1]AttributeName!$B:$B),"") | Q19: 0.08 | R19: 0.13 | S19: {=IFERROR(_xlfn.SWITCH(L19,1,_xlfn.XLOOKUP(O19,[1]AttributeName!$B:$B,[1]AttributeName!$D:$D),2,_xlfn.XLOOKUP(C19,#REF!,#REF!),3,_xlfn.XLOOKUP(C19,#REF!,#REF!)),0)} -> 0 | T19: {=IFERROR(_xlfn.SWITCH(L19,1,_xlfn.XLOOKUP(O19,[1]AttributeName!$B:$B,[1]AttributeName!$E:$E),2,_xlfn.XLOOKUP(C19,#REF!,#REF!),3,_xlfn.XLOOKUP(C19,#REF!,#REF!)),0)} -> 0
A20: =A12+1 -> 3 | B20: 1 | C20: 冰冷伤害倍率增加 | D20: 长剑 | E20: 前缀 | G20: 1 | H20: 50 | J20: {=_xlfn.SWITCH(B20,1,75,2,61,3,49,4,37,5,25,6,13,7,4,8,1)} -> 75 | K20: {=IFERROR(_xlfn.SWITCH(L20,2,_xlfn.XLOOKUP(C20,[1]ModifierDes!$B:$B,[1]ModifierDes!$C:$C),3,_xlfn.XLOOKUP(C20,[1]StuntDes!$B:$B,[1]StuntDes!$C:$C)),"")} -> 冰冷伤害倍率增加{0} | L20: =IF(M20="",IF(N20="",1,2),3) -> 2 | M20: =IFERROR(_xlfn.XLOOKUP(C20,[1]StuntDes!$B:$B,[1]StuntDes!$A:$A),"") | N20: =IFERROR(_xlfn.XLOOKUP(C20,[1]ModifierDes!$B:$B,[1]ModifierDes!$A:$A),"") -> 10058 | O20: =IFERROR(_xlfn.XLOOKUP(C20,[1]AttributeName!$C:$C,[1]AttributeName!$B:$B),"") | Q20: 0.5 | R20: 0.7 | S20: {=IFERROR(_xlfn.SWITCH(L20,1,_xlfn.XLOOKUP(O20,[1]AttributeName!$B:$B,[1]AttributeName!$D:$D),2,_xlfn.XLOOKUP(C20,#REF!,#REF!),3,_xlfn.XLOOKUP(C20,#REF!,#REF!)),0)} -> 0 | T20: {=IFERROR(_xlfn.SWITCH(L20,1,_xlfn.XLOOKUP(O20,[1]AttributeName!$B:$B,[1]AttributeName!$E:$E),2,_xlfn.XLOOKUP(C20,#REF!,#REF!),3,_xlfn.XLOOKUP(C20,#REF!,#REF!)),0)} -> 0
A21: =A13+1 -> 3 | B21: 2 | C21: 冰冷伤害倍率增加 | D21: 长剑 | E21: 前缀 | G21: 1 | H21: 100 | J21: {=_xlfn.SWITCH(B21,1,75,2,61,3,49,4,37,5,25,6,13,7,4,8,1)} -> 61 | K21: {=IFERROR(_xlfn.SWITCH(L21,2,_xlfn.XLOOKUP(C21,[1]ModifierDes!$B:$B,[1]ModifierDes!$C:$C),3,_xlfn.XLOOKUP(C21,[1]StuntDes!$B:$B,[1]StuntDes!$C:$C)),"")} -> 冰冷伤害倍率增加{0} | L21: =IF(M21="",IF(N21="",1,2),3) -> 2 | M21: =IFERROR(_xlfn.XLOOKUP(C21,[1]StuntDes!$B:$B,[1]StuntDes!$A:$A),"") | N21: =IFERROR(_xlfn.XLOOKUP(C21,[1]ModifierDes!$B:$B,[1]ModifierDes!$A:$A),"") -> 10058 | O21: =IFERROR(_xlfn.XLOOKUP(C21,[1]AttributeName!$C:$C,[1]AttributeName!$B:$B),"") | Q21: 0.44 | R21: 0.49 | S21: {=IFERROR(_xlfn.SWITCH(L21,1,_xlfn.XLOOKUP(O21,[1]AttributeName!$B:$B,[1]AttributeName!$D:$D),2,_xlfn.XLOOKUP(C21,#REF!,#REF!),3,_xlfn.XLOOKUP(C21,#REF!,#REF!)),0)} -> 0 | T21: {=IFERROR(_xlfn.SWITCH(L21,1,_xlfn.XLOOKUP(O21,[1]AttributeName!$B:$B,[1]AttributeName!$E:$E),2,_xlfn.XLOOKUP(C21,#REF!,#REF!),3,_xlfn.XLOOKUP(C21,#REF!,#REF!)),0)} -> 0
A22: =A14+1 -> 3 | B22: 3 | C22: 冰冷伤害倍率增加 | D22: 长剑 | E22: 前缀 | G22: 1 | H22: 200 | J22: {=_xlfn.SWITCH(B22,1,75,2,61,3,49,4,37,5,25,6,13,7,4,8,1)} -> 49 | K22: {=IFERROR(_xlfn.SWITCH(L22,2,_xlfn.XLOOKUP(C22,[1]ModifierDes!$B:$B,[1]ModifierDes!$C:$C),3,_xlfn.XLOOKUP(C22,[1]StuntDes!$B:$B,[1]StuntDes!$C:$C)),"")} -> 冰冷伤害倍率增加{0} | L22: =IF(M22="",IF(N22="",1,2),3) -> 2 | M22: =IFERROR(_xlfn.XLOOKUP(C22,[1]StuntDes!$B:$B,[1]StuntDes!$A:$A),"") | N22: =IFERROR(_xlfn.XLOOKUP(C22,[1]ModifierDes!$B:$B,[1]ModifierDes!$A:$A),"") -> 10058 | O22: =IFERROR(_xlfn.XLOOKUP(C22,[1]AttributeName!$C:$C,[1]AttributeName!$B:$B),"") | Q22: 0.38 | R22: 0.43 | S22: {=IFERROR(_xlfn.SWITCH(L22,1,_xlfn.XLOOKUP(O22,[1]AttributeName!$B:$B,[1]AttributeName!$D:$D),2,_xlfn.XLOOKUP(C22,#REF!,#REF!),3,_xlfn.XLOOKUP(C22,#REF!,#REF!)),0)} -> 0 | T22: {=IFERROR(_xlfn.SWITCH(L22,1,_xlfn.XLOOKUP(O22,[1]AttributeName!$B:$B,[1]AttributeName!$E:$E),2,_xlfn.XLOOKUP(C22,#REF!,#REF!),3,_xlfn.XLOOKUP(C22,#REF!,#REF!)),0)} -> 0
A23: =A15+1 -> 3 | B23: 4 | C23: 冰冷伤害倍率增加 | D23: 长剑 | E23: 前缀 | G23: 1 | H23: 500 | J23: {=_xlfn.SWITCH(B23,1,75,2,61,3,49,4,37,5,25,6,13,7,4,8,1)} -> 37 | K23: {=IFERROR(_xlfn.SWITCH(L23,2,_xlfn.XLOOKUP(C23,[1]ModifierDes!$B:$B,[1]ModifierDes!$C:$C),3,_xlfn.XLOOKUP(C23,[1]StuntDes!$B:$B,[1]StuntDes!$C:$C)),"")} -> 冰冷伤害倍率增加{0} | L23: =IF(M23="",IF(N23="",1,2),3) -> 2 | M23: =IFERROR(_xlfn.XLOOKUP(C23,[1]StuntDes!$B:$B,[1]StuntDes!$A:$A),"") | N23: =IFERROR(_xlfn.XLOOKUP(C23,[1]ModifierDes!$B:$B,[1]ModifierDes!$A:$A),"") -> 10058 | O23: =IFERROR(_xlfn.XLOOKUP(C23,[1]AttributeName!$C:$C,[1]AttributeName!$B:$B),"") | Q23: 0.32 | R23: 0.37 | S23: {=IFERROR(_xlfn.SWITCH(L23,1,_xlfn.XLOOKUP(O23,[1]AttributeName!$B:$B,[1]AttributeName!$D:$D),2,_xlfn.XLOOKUP(C23,#REF!,#REF!),3,_xlfn.XLOOKUP(C23,#REF!,#REF!)),0)} -> 0 | T23: {=IFERROR(_xlfn.SWITCH(L23,1,_xlfn.XLOOKUP(O23,[1]AttributeName!$B:$B,[1]AttributeName!$E:$E),2,_xlfn.XLOOKUP(C23,#REF!,#REF!),3,_xlfn.XLOOKUP(C23,#REF!,#REF!)),0)} -> 0
... A107: =A99+1 -> 13 | B107: 8 | C107: 命中率 | D107: 长剑 | E107: 前缀 | G107: 1 | H107: 1000 | J107: {=_xlfn.SWITCH(B107,1,75,2,61,3,49,4,37,5,25,6,13,7,4,8,1)} -> 1 | K107: {=IFERROR(_xlfn.SWITCH(L107,2,_xlfn.XLOOKUP(C107,[1]ModifierDes!$B:$B,[1]ModifierDes!$C:$C),3,_xlfn.XLOOKUP(C107,[1]StuntDes!$B:$B,[1]StuntDes!$C:$C)),"")} | L107: =IF(M107="",IF(N107="",1,2),3) -> 1 | M107: =IFERROR(_xlfn.XLOOKUP(C107,[1]StuntDes!$B:$B,[1]StuntDes!$A:$A),"") | N107: =IFERROR(_xlfn.XLOOKUP(C107,[1]ModifierDes!$B:$B,[1]ModifierDes!$A:$A),"") | O107: =IFERROR(_xlfn.XLOOKUP(C107,[1]AttributeName!$C:$C,[1]AttributeName!$B:$B),"") -> 10009 | Q107: 0.03 | R107: 0.04 | S107: {=IFERROR(_xlfn.SWITCH(L107,1,_xlfn.XLOOKUP(O107,[1]AttributeName!$B:$B,[1]AttributeName!$D:$D),2,_xlfn.XLOOKUP(C107,#REF!,#REF!),3,_xlfn.XLOOKUP(C107,#REF!,#REF!)),0)} -> 2 | T107: {=IFERROR(_xlfn.SWITCH(L107,1,_xlfn.XLOOKUP(O107,[1]AttributeName!$B:$B,[1]AttributeName!$E:$E),2,_xlfn.XLOOKUP(C107,#REF!,#REF!),3,_xlfn.XLOOKUP(C107,#REF!,#REF!)),0)} -> 2
A108: 51 | B108: 1 | C108: 魔力回复率提高 | D108: 长剑 | E108: 后缀 | G108: 2 | H108: 1000 | J108: {=_xlfn.SWITCH(B108,1,75,2,61,3,49,4,37,5,25,6,13,7,4,8,1)} -> 75 | K108: {=IFERROR(_xlfn.SWITCH(L108,2,_xlfn.XLOOKUP(C108,[1]ModifierDes!$B:$B,[1]ModifierDes!$C:$C),3,_xlfn.XLOOKUP(C108,[1]StuntDes!$B:$B,[1]StuntDes!$C:$C)),"")} -> 魔力回复率提高{0} | L108: =IF(M108="",IF(N108="",1,2),3) -> 2 | M108: =IFERROR(_xlfn.XLOOKUP(C108,[1]StuntDes!$B:$B,[1]StuntDes!$A:$A),"") | N108: =IFERROR(_xlfn.XLOOKUP(C108,[1]ModifierDes!$B:$B,[1]ModifierDes!$A:$A),"") -> 10116 | O108: =IFERROR(_xlfn.XLOOKUP(C108,[1]AttributeName!$C:$C,[1]AttributeName!$B:$B),"") | Q108: 0.36 | R108: 0.4 | S108: {=IFERROR(_xlfn.SWITCH(L108,1,_xlfn.XLOOKUP(O108,[1]AttributeName!$B:$B,[1]AttributeName!$D:$D),2,_xlfn.XLOOKUP(C108,#REF!,#REF!),3,_xlfn.XLOOKUP(C108,#REF!,#REF!)),0)} -> 0 | T108: {=IFERROR(_xlfn.SWITCH(L108,1,_xlfn.XLOOKUP(O108,[1]AttributeName!$B:$B,[1]AttributeName!$E:$E),2,_xlfn.XLOOKUP(C108,#REF!,#REF!),3,_xlfn.XLOOKUP(C108,#REF!,#REF!)),0)} -> 0
A109: 51 | B109: 2 | C109: 魔力回复率提高 | D109: 长剑 | E109: 后缀 | G109: 2 | H109: 1000 | J109: {=_xlfn.SWITCH(B109,1,75,2,61,3,49,4,37,5,25,6,13,7,4,8,1)} -> 61 | K109: {=IFERROR(_xlfn.SWITCH(L109,2,_xlfn.XLOOKUP(C109,[1]ModifierDes!$B:$B,[1]ModifierDes!$C:$C),3,_xlfn.XLOOKUP(C109,[1]StuntDes!$B:$B,[1]StuntDes!$C:$C)),"")} -> 魔力回复率提高{0} | L109: =IF(M109="",IF(N109="",1,2),3) -> 2 | M109: =IFERROR(_xlfn.XLOOKUP(C109,[1]StuntDes!$B:$B,[1]StuntDes!$A:$A),"") | N109: =IFERROR(_xlfn.XLOOKUP(C109,[1]ModifierDes!$B:$B,[1]ModifierDes!$A:$A),"") -> 10116 | O109: =IFERROR(_xlfn.XLOOKUP(C109,[1]AttributeName!$C:$C,[1]AttributeName!$B:$B),"") | Q109: 0.31 | R109: 0.35 | S109: {=IFERROR(_xlfn.SWITCH(L109,1,_xlfn.XLOOKUP(O109,[1]AttributeName!$B:$B,[1]AttributeName!$D:$D),2,_xlfn.XLOOKUP(C109,#REF!,#REF!),3,_xlfn.XLOOKUP(C109,#REF!,#REF!)),0)} -> 0 | T109: {=IFERROR(_xlfn.SWITCH(L109,1,_xlfn.XLOOKUP(O109,[1]AttributeName!$B:$B,[1]AttributeName!$E:$E),2,_xlfn.XLOOKUP(C109,#REF!,#REF!),3,_xlfn.XLOOKUP(C109,#REF!,#REF!)),0)} -> 0
A110: 51 | B110: 3 | C110: 魔力回复率提高 | D110: 长剑 | E110: 后缀 | G110: 2 | H110: 1000 | J110: {=_xlfn.SWITCH(B110,1,75,2,61,3,49,4,37,5,25,6,13,7,4,8,1)} -> 49 | K110: {=IFERROR(_xlfn.SWITCH(L110,2,_xlfn.XLOOKUP(C110,[1]ModifierDes!$B:$B,[1]ModifierDes!$C:$C),3,_xlfn.XLOOKUP(C110,[1]StuntDes!$B:$B,[1]StuntDes!$C:$C)),"")} -> 魔力回复率提高{0} | L110: =IF(M110="",IF(N110="",1,2),3) -> 2 | M110: =IFERROR(_xlfn.XLOOKUP(C110,[1]StuntDes!$B:$B,[1]StuntDes!$A:$A),"") | N110: =IFERROR(_xlfn.XLOOKUP(C110,[1]ModifierDes!$B:$B,[1]ModifierDes!$A:$A),"") -> 10116 | O110: =IFERROR(_xlfn.XLOOKUP(C110,[1]AttributeName!$C:$C,[1]AttributeName!$B:$B),"") | Q110: 0.26 | R110: 0.3 | S110: {=IFERROR(_xlfn.SWITCH(L110,1,_xlfn.XLOOKUP(O110,[1]AttributeName!$B:$B,[1]AttributeName!$D:$D),2,_xlfn.XLOOKUP(C110,#REF!,#REF!),3,_xlfn.XLOOKUP(C110,#REF!,#REF!)),0)} -> 0 | T110: {=IFERROR(_xlfn.SWITCH(L110,1,_xlfn.XLOOKUP(O110,[1]AttributeName!$B:$B,[1]AttributeName!$E:$E),2,_xlfn.XLOOKUP(C110,#REF!,#REF!),3,_xlfn.XLOOKUP(C110,#REF!,#REF!)),0)} -> 0
A111: 51 | B111: 4 | C111: 魔力回复率提高 | D111: 长剑 | E111: 后缀 | G111: 2 | H111: 1000 | J111: {=_xlfn.SWITCH(B111,1,75,2,61,3,49,4,37,5,25,6,13,7,4,8,1)} -> 37 | K111: {=IFERROR(_xlfn.SWITCH(L111,2,_xlfn.XLOOKUP(C111,[1]ModifierDes!$B:$B,[1]ModifierDes!$C:$C),3,_xlfn.XLOOKUP(C111,[1]StuntDes!$B:$B,[1]StuntDes!$C:$C)),"")} -> 魔力回复率提高{0} | L111: =IF(M111="",IF(N111="",1,2),3) -> 2 | M111: =IFERROR(_xlfn.XLOOKUP(C111,[1]StuntDes!$B:$B,[1]StuntDes!$A:$A),"") | N111: =IFERROR(_xlfn.XLOOKUP(C111,[1]ModifierDes!$B:$B,[1]ModifierDes!$A:$A),"") -> 10116 | O111: =IFERROR(_xlfn.XLOOKUP(C111,[1]AttributeName!$C:$C,[1]AttributeName!$B:$B),"") | Q111: 0.21 | R111: 0.25 | S111: {=IFERROR(_xlfn.SWITCH(L111,1,_xlfn.XLOOKUP(O111,[1]AttributeName!$B:$B,[1]AttributeName!$D:$D),2,_xlfn.XLOOKUP(C111,#REF!,#REF!),3,_xlfn.XLOOKUP(C111,#REF!,#REF!)),0)} -> 0 | T111: {=IFERROR(_xlfn.SWITCH(L111,1,_xlfn.XLOOKUP(O111,[1]AttributeName!$B:$B,[1]AttributeName!$E:$E),2,_xlfn.XLOOKUP(C111,#REF!,#REF!),3,_xlfn.XLOOKUP(C111,#REF!,#REF!)),0)} -> 0
A112: 51 | B112: 5 | C112: 魔力回复率提高 | D112: 长剑 | E112: 后缀 | G112: 2 | H112: 1000 | J112: {=_xlfn.SWITCH(B112,1,75,2,61,3,49,4,37,5,25,6,13,7,4,8,1)} -> 25 | K112: {=IFERROR(_xlfn.SWITCH(L112,2,_xlfn.XLOOKUP(C112,[1]ModifierDes!$B:$B,[1]ModifierDes!$C:$C),3,_xlfn.XLOOKUP(C112,[1]StuntDes!$B:$B,[1]StuntDes!$C:$C)),"")} -> 魔力回复率提高{0} | L112: =IF(M112="",IF(N112="",1,2),3) -> 2 | M112: =IFERROR(_xlfn.XLOOKUP(C112,[1]StuntDes!$B:$B,[1]StuntDes!$A:$A),"") | N112: =IFERROR(_xlfn.XLOOKUP(C112,[1]ModifierDes!$B:$B,[1]ModifierDes!$A:$A),"") -> 10116 | O112: =IFERROR(_xlfn.XLOOKUP(C112,[1]AttributeName!$C:$C,[1]AttributeName!$B:$B),"") | Q112: 0.16 | R112: 0.2 | S112: {=IFERROR(_xlfn.SWITCH(L112,1,_xlfn.XLOOKUP(O112,[1]AttributeName!$B:$B,[1]AttributeName!$D:$D),2,_xlfn.XLOOKUP(C112,#REF!,#REF!),3,_xlfn.XLOOKUP(C112,#REF!,#REF!)),0)} -> 0 | T112: {=IFERROR(_xlfn.SWITCH(L112,1,_xlfn.XLOOKUP(O112,[1]AttributeName!$B:$B,[1]AttributeName!$E:$E),2,_xlfn.XLOOKUP(C112,#REF!,#REF!),3,_xlfn.XLOOKUP(C112,#REF!,#REF!)),0)} -> 0
A113: 51 | B113: 6 | C113: 魔力回复率提高 | D113: 长剑 | E113: 后缀 | G113: 2 | H113: 1000 | J113: {=_xlfn.SWITCH(B113,1,75,2,61,3,49,4,37,5,25,6,13,7,4,8,1)} -> 13 | K113: {=IFERROR(_xlfn.SWITCH(L113,2,_xlfn.XLOOKUP(C113,[1]ModifierDes!$B:$B,[1]ModifierDes!$C:$C),3,_xlfn.XLOOKUP(C113,[1]StuntDes!$B:$B,[1]StuntDes!$C:$C)),"")} -> 魔力回复率提高{0} | L113: =IF(M113="",IF(N113="",1,2),3) -> 2 | M113: =IFERROR(_xlfn.XLOOKUP(C113,[1]StuntDes!$B:$B,[1]StuntDes!$A:$A),"") | N113: =IFERROR(_xlfn.XLOOKUP(C113,[1]ModifierDes!$B:$B,[1]ModifierDes!$A:$A),"") -> 10116 | O113: =IFERROR(_xlfn.XLOOKUP(C113,[1]AttributeName!$C:$C,[1]AttributeName!$B:$B),"") | Q113: 0.11 | R113: 0.15 | S113: {=IFERROR(_xlfn.SWITCH(L113,1,_xlfn.XLOOKUP(O113,[1]AttributeName!$B:$B,[1]AttributeName!$D:$D),2,_xlfn.XLOOKUP(C113,#REF!,#REF!),3,_xlfn.XLOOKUP(C113,#REF!,#REF!)),0)} -> 0 | T113: {=IFERROR(_xlfn.SWITCH(L113,1,_xlfn.XLOOKUP(O113,[1]AttributeName!$B:$B,[1]AttributeName!$E:$E),2,_xlfn.XLOOKUP(C113,#REF!,#REF!),3,_xlfn.XLOOKUP(C113,#REF!,#REF!)),0)} -> 0
A114: 51 | B114: 7 | C114: 魔力回复率提高 | D114: 长剑 | E114: 后缀 | G114: 2 | H114: 1000 | J114: {=_xlfn.SWITCH(B114,1,75,2,61,3,49,4,37,5,25,6,13,7,4,8,1)} -> 4 | K114: {=IFERROR(_xlfn.SWITCH(L114,2,_xlfn.XLOOKUP(C114,[1]ModifierDes!$B:$B,[1]ModifierDes!$C:$C),3,_xlfn.XLOOKUP(C114,[1]StuntDes!$B:$B,[1]StuntDes!$C:$C)),"")} -> 魔力回复率提高{0} | L114: =IF(M114="",IF(N114="",1,2),3) -> 2 | M114: =IFERROR(_xlfn.XLOOKUP(C114,[1]StuntDes!$B:$B,[1]StuntDes!$A:$A),"") | N114: =IFERROR(_xlfn.XLOOKUP(C114,[1]ModifierDes!$B:$B,[1]ModifierDes!$A:$A),"") -> 10116 | O114: =IFERROR(_xlfn.XLOOKUP(C114,[1]AttributeName!$C:$C,[1]AttributeName!$B:$B),"") | Q114: 0.05 | R114: 0.1 | S114: {=IFERROR(_xlfn.SWITCH(L114,1,_xlfn.XLOOKUP(O114,[1]AttributeName!$B:$B,[1]AttributeName!$D:$D),2,_xlfn.XLOOKUP(C114,#REF!,#REF!),3,_xlfn.XLOOKUP(C114,#REF!,#REF!)),0)} -> 0 | T114: {=IFERROR(_xlfn.SWITCH(L114,1,_xlfn.XLOOKUP(O114,[1]AttributeName!$B:$B,[1]AttributeName!$E:$E),2,_xlfn.XLOOKUP(C114,#REF!,#REF!),3,_xlfn.XLOOKUP(C114,#REF!,#REF!)),0)} -> 0
A115: 51 | B115: 8 | C115: 魔力回复率提高 | D115: 长剑 | E115: 后缀 | G115: 2 | H115: 1000 | J115: {=_xlfn.SWITCH(B115,1,75,2,61,3,49,4,37,5,25,6,13,7,4,8,1)} -> 1 | K115: {=IFERROR(_xlfn.SWITCH(L115,2,_xlfn.XLOOKUP(C115,[1]ModifierDes!$B:$B,[1]ModifierDes!$C:$C),3,_xlfn.XLOOKUP(C115,[1]StuntDes!$B:$B,[1]StuntDes!$C:$C)),"")} -> 魔力回复率提高{0} | L115: =IF(M115="",IF(N115="",1,2),3) -> 2 | M115: =IFERROR(_xlfn.XLOOKUP(C115,[1]StuntDes!$B:$B,[1]StuntDes!$A:$A),"") | N115: =IFERROR(_xlfn.XLOOKUP(C115,[1]ModifierDes!$B:$B,[1]ModifierDes!$A:$A),"") -> 10116 | O115: =IFERROR(_xlfn.XLOOKUP(C115,[1]AttributeName!$C:$C,[1]AttributeName!$B:$B),"") | Q115: 0.03 | R115: 0.04 | S115: {=IFERROR(_xlfn.SWITCH(L115,1,_xlfn.XLOOKUP(O115,[1]AttributeName!$B:$B,[1]AttributeName!$D:$D),2,_xlfn.XLOOKUP(C115,#REF!,#REF!),3,_xlfn.XLOOKUP(C115,#REF!,#REF!)),0)} -> 0 | T115: {=IFERROR(_xlfn.SWITCH(L115,1,_xlfn.XLOOKUP(O115,[1]AttributeName!$B:$B,[1]AttributeName!$E:$E),2,_xlfn.XLOOKUP(C115,#REF!,#REF!),3,_xlfn.XLOOKUP(C115,#REF!,#REF!)),0)} -> 0
A116: 52 | B116: 2 | C116: 攻击技能等级 | D116: 长剑 | E116: 后缀 | G116: 2 | H116: 50 | I116: 2 | J116: {=_xlfn.SWITCH(B116,1,75,2,61,3,49,4,37,5,25,6,13,7,4,8,1)} -> 61 | K116: {=IFERROR(_xlfn.SWITCH(L116,2,_xlfn.XLOOKUP(C116,[1]ModifierDes!$B:$B,[1]ModifierDes!$C:$C),3,_xlfn.XLOOKUP(C116,[1]StuntDes!$B:$B,[1]StuntDes!$C:$C)),"")} | L116: =IF(M116="",IF(N116="",1,2),3) -> 1 | M116: =IFERROR(_xlfn.XLOOKUP(C116,[1]StuntDes!$B:$B,[1]StuntDes!$A:$A),"") | N116: =IFERROR(_xlfn.XLOOKUP(C116,[1]ModifierDes!$B:$B,[1]ModifierDes!$A:$A),"") | O116: =IFERROR(_xlfn.XLOOKUP(C116,[1]AttributeName!$C:$C,[1]AttributeName!$B:$B),"") -> 10401 | Q116: 4 | R116: 5 | S116: {=IFERROR(_xlfn.SWITCH(L116,1,_xlfn.XLOOKUP(O116,[1]AttributeName!$B:$B,[1]AttributeName!$D:$D),2,_xlfn.XLOOKUP(C116,#REF!,#REF!),3,_xlfn.XLOOKUP(C116,#REF!,#REF!)),0)} -> 0 | T116: {=IFERROR(_xlfn.SWITCH(L116,1,_xlfn.XLOOKUP(O116,[1]AttributeName!$B:$B,[1]AttributeName!$E:$E),2,_xlfn.XLOOKUP(C116,#REF!,#REF!),3,_xlfn.XLOOKUP(C116,#REF!,#REF!)),0)} -> 1
A117: 52 | B117: 4 | C117: 攻击技能等级 | D117: 长剑 | E117: 后缀 | G117: 2 | H117: 100 | I117: 2 | J117: {=_xlfn.SWITCH(B117,1,75,2,61,3,49,4,37,5,25,6,13,7,4,8,1)} -> 37 | K117: {=IFERROR(_xlfn.SWITCH(L117,2,_xlfn.XLOOKUP(C117,[1]ModifierDes!$B:$B,[1]ModifierDes!$C:$C),3,_xlfn.XLOOKUP(C117,[1]StuntDes!$B:$B,[1]StuntDes!$C:$C)),"")} | L117: =IF(M117="",IF(N117="",1,2),3) -> 1 | M117: =IFERROR(_xlfn.XLOOKUP(C117,[1]StuntDes!$B:$B,[1]StuntDes!$A:$A),"") | N117: =IFERROR(_xlfn.XLOOKUP(C117,[1]ModifierDes!$B:$B,[1]ModifierDes!$A:$A),"") | O117: =IFERROR(_xlfn.XLOOKUP(C117,[1]AttributeName!$C:$C,[1]AttributeName!$B:$B),"") -> 10401 | Q117: 2 | R117: 3 | S117: {=IFERROR(_xlfn.SWITCH(L117,1,_xlfn.XLOOKUP(O117,[1]AttributeName!$B:$B,[1]AttributeName!$D:$D),2,_xlfn.XLOOKUP(C117,#REF!,#REF!),3,_xlfn.XLOOKUP(C117,#REF!,#REF!)),0)} -> 0 | T117: {=IFERROR(_xlfn.SWITCH(L117,1,_xlfn.XLOOKUP(O117,[1]AttributeName!$B:$B,[1]AttributeName!$E:$E),2,_xlfn.XLOOKUP(C117,#REF!,#REF!),3,_xlfn.XLOOKUP(C117,#REF!,#REF!)),0)} -> 1
A118: 52 | B118: 6 | C118: 攻击技能等级 | D118: 长剑 | E118: 后缀 | G118: 2 | H118: 200 | I118: 2 | J118: {=_xlfn.SWITCH(B118,1,75,2,61,3,49,4,37,5,25,6,13,7,4,8,1)} -> 13 | K118: {=IFERROR(_xlfn.SWITCH(L118,2,_xlfn.XLOOKUP(C118,[1]ModifierDes!$B:$B,[1]ModifierDes!$C:$C),3,_xlfn.XLOOKUP(C118,[1]StuntDes!$B:$B,[1]StuntDes!$C:$C)),"")} | L118: =IF(M118="",IF(N118="",1,2),3) -> 1 | M118: =IFERROR(_xlfn.XLOOKUP(C118,[1]StuntDes!$B:$B,[1]StuntDes!$A:$A),"") | N118: =IFERROR(_xlfn.XLOOKUP(C118,[1]ModifierDes!$B:$B,[1]ModifierDes!$A:$A),"") | O118: =IFERROR(_xlfn.XLOOKUP(C118,[1]AttributeName!$C:$C,[1]AttributeName!$B:$B),"") -> 10401 | Q118: 1 | R118: 1 | S118: {=IFERROR(_xlfn.SWITCH(L118,1,_xlfn.XLOOKUP(O118,[1]AttributeName!$B:$B,[1]AttributeName!$D:$D),2,_xlfn.XLOOKUP(C118,#REF!,#REF!),3,_xlfn.XLOOKUP(C118,#REF!,#REF!)),0)} -> 0 | T118: {=IFERROR(_xlfn.SWITCH(L118,1,_xlfn.XLOOKUP(O118,[1]AttributeName!$B:$B,[1]AttributeName!$E:$E),2,_xlfn.XLOOKUP(C118,#REF!,#REF!),3,_xlfn.XLOOKUP(C118,#REF!,#REF!)),0)} -> 1
A119: =A116+1 -> 53 | B119: 1 | C119: 物理技能等级 | D119: 长剑 | E119: 后缀 | G119: 2 | H119: 100 | I119: 2 | J119: {=_xlfn.SWITCH(B119,1,75,2,61,3,49,4,37,5,25,6,13,7,4,8,1)} -> 75 | K119: {=IFERROR(_xlfn.SWITCH(L119,2,_xlfn.XLOOKUP(C119,[1]ModifierDes!$B:$B,[1]ModifierDes!$C:$C),3,_xlfn.XLOOKUP(C119,[1]StuntDes!$B:$B,[1]StuntDes!$C:$C)),"")} | L119: =IF(M119="",IF(N119="",1,2),3) -> 1 | M119: =IFERROR(_xlfn.XLOOKUP(C119,[1]StuntDes!$B:$B,[1]StuntDes!$A:$A),"") | N119: =IFERROR(_xlfn.XLOOKUP(C119,[1]ModifierDes!$B:$B,[1]ModifierDes!$A:$A),"") | O119: =IFERROR(_xlfn.XLOOKUP(C119,[1]AttributeName!$C:$C,[1]AttributeName!$B:$B),"") -> 10403 | Q119: 4 | R119: 6 | S119: {=IFERROR(_xlfn.SWITCH(L119,1,_xlfn.XLOOKUP(O119,[1]AttributeName!$B:$B,[1]AttributeName!$D:$D),2,_xlfn.XLOOKUP(C119,#REF!,#REF!),3,_xlfn.XLOOKUP(C119,#REF!,#REF!)),0)} -> 0 | T119: {=IFERROR(_xlfn.SWITCH(L119,1,_xlfn.XLOOKUP(O119,[1]AttributeName!$B:$B,[1]AttributeName!$E:$E),2,_xlfn.XLOOKUP(C119,#REF!,#REF!),3,_xlfn.XLOOKUP(C119,#REF!,#REF!)),0)} -> 1
A120: =A117+1 -> 53 | B120: 3 | C120: 物理技能等级 | D120: 长剑 | E120: 后缀 | G120: 2 | H120: 200 | I120: 2 | J120: {=_xlfn.SWITCH(B120,1,75,2,61,3,49,4,37,5,25,6,13,7,4,8,1)} -> 49 | K120: {=IFERROR(_xlfn.SWITCH(L120,2,_xlfn.XLOOKUP(C120,[1]ModifierDes!$B:$B,[1]ModifierDes!$C:$C),3,_xlfn.XLOOKUP(C120,[1]StuntDes!$B:$B,[1]StuntDes!$C:$C)),"")} | L120: =IF(M120="",IF(N120="",1,2),3) -> 1 | M120: =IFERROR(_xlfn.XLOOKUP(C120,[1]StuntDes!$B:$B,[1]StuntDes!$A:$A),"") | N120: =IFERROR(_xlfn.XLOOKUP(C120,[1]ModifierDes!$B:$B,[1]ModifierDes!$A:$A),"") | O120: =IFERROR(_xlfn.XLOOKUP(C120,[1]AttributeName!$C:$C,[1]AttributeName!$B:$B),"") -> 10403 | Q120: 2 | R120: 3 | S120: {=IFERROR(_xlfn.SWITCH(L120,1,_xlfn.XLOOKUP(O120,[1]AttributeName!$B:$B,[1]AttributeName!$D:$D),2,_xlfn.XLOOKUP(C120,#REF!,#REF!),3,_xlfn.XLOOKUP(C120,#REF!,#REF!)),0)} -> 0 | T120: {=IFERROR(_xlfn.SWITCH(L120,1,_xlfn.XLOOKUP(O120,[1]AttributeName!$B:$B,[1]AttributeName!$E:$E),2,_xlfn.XLOOKUP(C120,#REF!,#REF!),3,_xlfn.XLOOKUP(C120,#REF!,#REF!)),0)} -> 1
A121: =A118+1 -> 53 | B121: 5 | C121: 物理技能等级 | D121: 长剑 | E121: 后缀 | G121: 2 | H121: 500 | I121: 2 | J121: {=_xlfn.SWITCH(B121,1,75,2,61,3,49,4,37,5,25,6,13,7,4,8,1)} -> 25 | K121: {=IFERROR(_xlfn.SWITCH(L121,2,_xlfn.XLOOKUP(C121,[1]ModifierDes!$B:$B,[1]ModifierDes!$C:$C),3,_xlfn.XLOOKUP(C121,[1]StuntDes!$B:$B,[1]StuntDes!$C:$C)),"")} | L121: =IF(M121="",IF(N121="",1,2),3) -> 1 | M121: =IFERROR(_xlfn.XLOOKUP(C121,[1]StuntDes!$B:$B,[1]StuntDes!$A:$A),"") | N121: =IFERROR(_xlfn.XLOOKUP(C121,[1]ModifierDes!$B:$B,[1]ModifierDes!$A:$A),"") | O121: =IFERROR(_xlfn.XLOOKUP(C121,[1]AttributeName!$C:$C,[1]AttributeName!$B:$B),"") -> 10403 | Q121: 1 | R121: 1 | S121: {=IFERROR(_xlfn.SWITCH(L121,1,_xlfn.XLOOKUP(O121,[1]AttributeName!$B:$B,[1]AttributeName!$D:$D),2,_xlfn.XLOOKUP(C121,#REF!,#REF!),3,_xlfn.XLOOKUP(C121,#REF!,#REF!)),0)} -> 0 | T121: {=IFERROR(_xlfn.SWITCH(L121,1,_xlfn.XLOOKUP(O121,[1]AttributeName!$B:$B,[1]AttributeName!$E:$E),2,_xlfn.XLOOKUP(C121,#REF!,#REF!),3,_xlfn.XLOOKUP(C121,#REF!,#REF!)),0)} -> 1
A122: =A119+1 -> 54 | B122: =B119 -> 1 | C122: 火焰技能等级 | D122: 长剑 | E122: 后缀 | G122: 2 | H122: 100 | I122: 2 | J122: {=_xlfn.SWITCH(B122,1,75,2,61,3,49,4,37,5,25,6,13,7,4,8,1)} -> 75 | K122: {=IFERROR(_xlfn.SWITCH(L122,2,_xlfn.XLOOKUP(C122,[1]ModifierDes!$B:$B,[1]ModifierDes!$C:$C),3,_xlfn.XLOOKUP(C122,[1]StuntDes!$B:$B,[1]StuntDes!$C:$C)),"")} | L122: =IF(M122="",IF(N122="",1,2),3) -> 1 | M122: =IFERROR(_xlfn.XLOOKUP(C122,[1]StuntDes!$B:$B,[1]StuntDes!$A:$A),"") | N122: =IFERROR(_xlfn.XLOOKUP(C122,[1]ModifierDes!$B:$B,[1]ModifierDes!$A:$A),"") | O122: =IFERROR(_xlfn.XLOOKUP(C122,[1]AttributeName!$C:$C,[1]AttributeName!$B:$B),"") -> 10404 | Q122: 4 | R122: 6 | S122: {=IFERROR(_xlfn.SWITCH(L122,1,_xlfn.XLOOKUP(O122,[1]AttributeName!$B:$B,[1]AttributeName!$D:$D),2,_xlfn.XLOOKUP(C122,#REF!,#REF!),3,_xlfn.XLOOKUP(C122,#REF!,#REF!)),0)} -> 0 | T122: {=IFERROR(_xlfn.SWITCH(L122,1,_xlfn.XLOOKUP(O122,[1]AttributeName!$B:$B,[1]AttributeName!$E:$E),2,_xlfn.XLOOKUP(C122,#REF!,#REF!),3,_xlfn.XLOOKUP(C122,#REF!,#REF!)),0)} -> 1
A123: =A120+1 -> 54 | B123: =B120 -> 3 | C123: 火焰技能等级 | D123: 长剑 | E123: 后缀 | G123: 2 | H123: 200 | I123: 2 | J123: {=_xlfn.SWITCH(B123,1,75,2,61,3,49,4,37,5,25,6,13,7,4,8,1)} -> 49 | K123: {=IFERROR(_xlfn.SWITCH(L123,2,_xlfn.XLOOKUP(C123,[1]ModifierDes!$B:$B,[1]ModifierDes!$C:$C),3,_xlfn.XLOOKUP(C123,[1]StuntDes!$B:$B,[1]StuntDes!$C:$C)),"")} | L123: =IF(M123="",IF(N123="",1,2),3) -> 1 | M123: =IFERROR(_xlfn.XLOOKUP(C123,[1]StuntDes!$B:$B,[1]StuntDes!$A:$A),"") | N123: =IFERROR(_xlfn.XLOOKUP(C123,[1]ModifierDes!$B:$B,[1]ModifierDes!$A:$A),"") | O123: =IFERROR(_xlfn.XLOOKUP(C123,[1]AttributeName!$C:$C,[1]AttributeName!$B:$B),"") -> 10404 | Q123: 2 | R123: 3 | S123: {=IFERROR(_xlfn.SWITCH(L123,1,_xlfn.XLOOKUP(O123,[1]AttributeName!$B:$B,[1]AttributeName!$D:$D),2,_xlfn.XLOOKUP(C123,#REF!,#REF!),3,_xlfn.XLOOKUP(C123,#REF!,#REF!)),0)} -> 0 | T123: {=IFERROR(_xlfn.SWITCH(L123,1,_xlfn.XLOOKUP(O123,[1]AttributeName!$B:$B,[1]AttributeName!$E:$E),2,_xlfn.XLOOKUP(C123,#REF!,#REF!),3,_xlfn.XLOOKUP(C123,#REF!,#REF!)),0)} -> 1
...

Sheet EquipModifierValue
A1: 词缀t级 | B1: 价值碎钻
A2: tier.p | B2: value
A3: number | B3: number2
A4: 1 | B4: 30
A5: 2 | B5: 15
A6: 3 | B6: 9
A7: 4 | B7: 5
A8: 5 | B8: 3
A9: 6 | B9: 2
A10: 7 | B10: 1
A11: 8 | B11: 0

Sheet ModifierTier
A1: 评级 | B1: 评级底 | C1: 字色 | D1: 描边
A2: tier.p | B2: res | C2: color | D2: outline
A3: number | B3: string | C3: string | D3: string
A4: 0 | B4: 8 | C4: FFF6E4 | D4: AF272A
A5: 1 | B5: 6 | C5: FFF6E4 | D5: A65310
A6: 2 | B6: =B5 -> 6 | C6: =C5 -> FFF6E4 | D6: =D5 -> A65310
A7: 3 | B7: 5 | C7: FEEAEA | D7: A95B00
A8: 4 | B8: =B7 -> 5 | C8: =C7 -> FEEAEA | D8: =D7 -> A95B00
A9: 5 | B9: 4 | C9: FEE9FF | D9: 8426AC
A10: 6 | B10: 4 | C10: =C9 -> FEE9FF | D10: =D9 -> 8426AC
A11: 7 | B11: 3 | C11: E7F9FF | D11: 2D56AB
A12: 8 | B12: 3 | C12: =C11 -> E7F9FF | D12: =D11 -> 2D56AB

Sheet |词缀透视
A2: (nouse)所属type | B2: 武器
A3: (nouse)所属词位 | B3: 后缀
A5: id | B5: 备注(nouse) | C5: 评级 | D5: 求和项:权重
A6: 11501 | D6: 0.0055248619
B7: 投射物技能等级 | D7: 0.0055248619
C8: 1 | D8: 0.0018416206
C9: 3 | D9: 0.0036832413
A10: 11502 | D10: 0.0027624309
B11: 攻击技能等级 | D11: 0.0027624309
C12: 1 | D12: 0.00092081031
C13: 3 | D13: 0.0018416206
A14: 11503 | D14: 0.0027624309
B15: 法术技能等级 | D15: 0.0027624309
C16: 1 | D16: 0.00092081031
C17: 3 | D17: 0.0018416206
A18: 11504 | D18: 0.0055248619
B19: 物理技能等级 | D19: 0.0055248619
C20: 1 | D20: 0.0018416206
